Workbook
Name D2D_Միացումներ: #REF!
Name D2D_Սակագին: #REF!
Name D2D_Տոկոս: #REF!
Name Առաջնահերթ_Ցանկ: #REF!
Name Առողջ_Գումար: #REF!
Name Աստիճան_Բոնուս: #REF!
Name Աստիճան_Շեմ: #REF!
Name Բաժինների_Ցանկ: #REF!
Name Դրոշմ_Գումար: #REF!
Name Դրոշմ_Զուտ_Սահման: #REF!
Name Եկամտային_Հարկ: #REF!
Name Կուտակային: #REF!
Name Հարկ_Գործակից: #REF!
Name Մոդելների_Ցանկ: #REF!
Name Պաշտոնների_Ցանկ: KPI!$C$14:$C$44

Sheet Ամփոփ պատկեր
B2: ԱՄՓՈՓ ՊԱՏԿԵՐ
B4: ԿԱԶՄԱԿԵՐՊՈՒԹՅՈՒՆ
B6: ԸՆԴԱՄԵՆԸ ՀԱՍՏԻՔ | E6: ՀԱՄԱԼՐՎԱԾ | H6: ԹԱՓՈՒՐ | K6: ԼՐԱՑՎԱԾՈՒԹՅՈՒՆ
B7: ='Կառուցվածք և աշխատավարձ'!$F$55-'Կառուցվածք և աշխատավարձ'!$F$53 -> 52 | E7: ='Կառուցվածք և աշխատավարձ'!$G$55-'Կառուցվածք և աշխատավարձ'!$G$53 -> 25 | H7: ='Կառուցվածք և աշխատավարձ'!$H$55-'Կառուցվածք և աշխատավարձ'!$H$53 -> 27 | K7: =('Կառուցվածք և աշխատավարձ'!$G$55-'Կառուցվածք և աշխատավարձ'!$G$53)/('Կառուցվածք և աշխատավարձ'!$F$55-'Կառուցվածք և աշխատավարձ'!$F$53) -> 0.48076923
B8: 52 հաստիք։ + 2 ԱՁ + 3 ղեկավար (CEO/CTO/S&O) = 57 ընդամենը | E8: Փաստացի աշխատող մարդ | H8: Բացվող հաստիքներ (առանց ԱՁ) | K8: Համալրված ÷ ընդամենը
B10: ԱՄՍԱԿԱՆ ԱՇԽԱՏԱՎԱՐՁԱՅԻՆ ԲԵՌ (֏)
B12: ՖԻՔՍ՝ ՄԱՔՈՒՐ | E12: ՖԻՔՍԻ ԲԱԶԱ՝ ՀԱՐԿԵՐՈՎ | H12: ԲԱԶԱՅԻՆ ՍՑԵՆԱՐ՝ ՀԱՐԿԵՐՈՎ | K12: ՏԱՐԵԿԱՆ՝ ԲԱԶԱՅԻՆ
B13: ='Կառուցվածք և աշխատավարձ'!$P$55 -> 8310000 | E13: ='Կառուցվածք և աշխատավարձ'!$Q$55 -> 11464133 | H13: ='Կառուցվածք և աշխատավարձ'!$AA$55 -> 15695333 | K13: ='Կառուցվածք և աշխատավարձ'!$AA$55*12 -> 188344000
B14: Առանց բոնուսի՝ 52 հաստիք + 2 ԱՁ | E14: Հաշվարկային բազա։ Հատակ չէ — D2D-ն շեմից ցածր ֆիքս չի ստանում | H14: Կատարում 100–119% (բոնուս +35%) | K14: ="Հատակ "&TEXT('Կառուցվածք և աշխատավարձ'!$X$55*12,"#,##0")&" · Առաստաղ "&TEXT('Կառուցվածք և աշխատավարձ'!$AB$55*12,"#,##0")&" ֏/տարի" -> Հատակ 135,227,200 · Առաստաղ 208,705,600 ֏/տարի
B16: ՀԱՏԱԿ՝ ԱՄՍԱԿԱՆ (<80%) | E16: ԱՌԱՍՏԱՂ՝ ԱՄՍԱԿԱՆ (≥120%) | H16: ՓԱՍՏԱՑԻ ԱՅՍՕՐ | K16: ԹԱՓՈՒՐԻ ԱՐԺԵՔԸ
B17: ='Կառուցվածք և աշխատավարձ'!$X$55 -> 11268933 | E17: ='Կառուցվածք և աշխատավարձ'!$AB$55 -> 17392133 | H17: =SUMPRODUCT('Կառուցվածք և աշխատավարձ'!$O$7:$O16,'Կառուցվածք և աշխատավարձ'!$G$7:$G16)+SUMPRODUCT('Կառուցվածք և աշխատավարձ'!$O$22:$O$35,'Կառուցվածք և աշխատավարձ'!$G$22:$G$35)+SUMPRODUCT('Կառուցվածք և աշխատավարձ'!$O$39:$O$42,'Կառուցվածք և աշխատավարձ'!$G$39:$G$42)+SUMPRODUCT('Կառուցվածք և աշխատավարձ'!$O$46:$O$47,'Կառուցվածք և աշխատավարձ'!$G$46:$G$47)+SUMPRODUCT('Կառուցվածք և աշխատավարձ'!$O$51:$O$52,'Կառուցվածք և աշխատավարձ'!$G$51:$G$52) -> 6372000 | K17: =SUMPRODUCT('Կառուցվածք և աշխատավարձ'!$O$7:$O16,'Կառուցվածք և աշխատավարձ'!$H$7:$H16)+SUMPRODUCT('Կառուցվածք և աշխատավարձ'!$O$22:$O$35,'Կառուցվածք և աշխատավարձ'!$H$22:$H$35)+SUMPRODUCT('Կառուցվածք և աշխատավարձ'!$O$39:$O$42,'Կառուցվածք և աշխատավարձ'!$H$39:$H$42)+SUMPRODUCT('Կառուցվածք և աշխատավարձ'!$O$46:$O$47,'Կառուցվածք և աշխատավարձ'!$H$46:$H$47)+SUMPRODUCT('Կառուցվածք և աշխատավարձ'!$O$51:$O$52,'Կառուցվածք և աշխատավարձ'!$H$51:$H$52) -> 5092133.3
B18: Ամենացածր հնարավոր ելք, հարկերով | E18: Ամենաբարձր հնարավոր ելք, հարկերով | H18: Միայն համալրված հաստիքները, ֆիքս հարկերով | K18: Ինչ կավելանա լրիվ համալրվելիս
B20: ԵՐԵՔ ԹԻՎ | E20: ԱՄՍԱԿԱՆ, ՀԱՐԿԵՐՈՎ (֏) | H20: ԻՆՉ Է ՆԵՐԱՌՈՒՄ | K20: ՀԱՇՎԱՐԿ
B21: ՀԻՄԱ ՈՒՆԵՆՔ | E21: =SUMPRODUCT('Կառուցվածք և աշխատավարձ'!$O$7:$O16,'Կառուցվածք և աշխատավարձ'!$G$7:$G16)+SUMPRODUCT('Կառուցվածք և աշխատավարձ'!$O$22:$O$35,'Կառուցվածք և աշխատավարձ'!$G$22:$G$35)+SUMPRODUCT('Կառուցվածք և աշխատավարձ'!$O$39:$O$42,'Կառուցվածք և աշխատավարձ'!$G$39:$G$42)+SUMPRODUCT('Կառուցվածք և աշխատավարձ'!$O$46:$O$47,'Կառուցվածք և աշխատավարձ'!$G$46:$G$47)+SUMPRODUCT('Կառուցվածք և աշխատավարձ'!$O$51:$O$52,'Կառուցվածք և աշխատավարձ'!$G$51:$G$52) -> 6372000 | H21: Միայն համալրված հաստիքները, ֆիքս | K21: Ֆիքս հարկերով × համալրված
B22: ՄԵՆԱԿ ԿՐԻՏԻԿԱԿԱՆԸ | E22: =SUMPRODUCT('Կառուցվածք և աշխատավարձ'!$O$7:$O$16,'Կառուցվածք և աշխատավարձ'!$H$7:$H$16,--('Կառուցվածք և աշխատավարձ'!$I$7:$I$16="Կրիտիկական"))+SUMPRODUCT('Կառուցվածք և աշխատավարձ'!$O$22:$O$35,'Կառուցվածք և աշխատավարձ'!$H$22:$H$35,--('Կառուցվածք և աշխատավարձ'!$I$22:$I$35="Կրիտիկական"))+SUMPRODUCT('Կառուցվածք և աշխատավարձ'!$O$39:$O$42,'Կառուցվածք և աշխատավարձ'!$H$39:$H$42,--('Կառուցվածք և աշխատավարձ'!$I$39:$I$42="Կրիտիկական"))+SUMPRODUCT('Կառուցվածք և աշխատավարձ'!$O$46:$O$47,'Կառուցվածք և աշխատավարձ'!$H$46:$H$47,--('Կառուցվածք և աշխատավարձ'!$I$46:$I$47="Կրիտիկական"))+SUMPRODUCT('Կառուցվածք և աշխատավարձ'!$O$51:$O$52,'Կառուցվածք և աշխատավարձ'!$H$51:$H$52,--('Կառուցվածք և աշխատավարձ'!$I$51:$I$52="Կրիտիկական")) -> 1807200 | H22: Միայն կրիտիկական թափուր հաստիքները | K22: Ֆիքս հարկերով × կրիտիկական թափուր
B23: ՀԻՄԱ + ԿՐԻՏԻԿԱԿԱՆ | E23: =$E$21+SUMPRODUCT('Կառուցվածք և աշխատավարձ'!$O$7:$O$16,'Կառուցվածք և աշխատավարձ'!$H$7:$H$16,--('Կառուցվածք և աշխատավարձ'!$I$7:$I$16="Կրիտիկական"))+SUMPRODUCT('Կառուցվածք և աշխատավարձ'!$O$22:$O$35,'Կառուցվածք և աշխատավարձ'!$H$22:$H$35,--('Կառուցվածք և աշխատավարձ'!$I$22:$I$35="Կրիտիկական"))+SUMPRODUCT('Կառուցվածք և աշխատավարձ'!$O$39:$O$42,'Կառուցվածք և աշխատավարձ'!$H$39:$H$42,--('Կառուցվածք և աշխատավարձ'!$I$39:$I$42="Կրիտիկական"))+SUMPRODUCT('Կառուցվածք և աշխատավարձ'!$O$46:$O$47,'Կառուցվածք և աշխատավարձ'!$H$46:$H$47,--('Կառուցվածք և աշխատավարձ'!$I$46:$I$47="Կրիտիկական"))+SUMPRODUCT('Կառուցվածք և աշխատավարձ'!$O$51:$O$52,'Կառուցվածք և աշխատավարձ'!$H$51:$H$52,--('Կառուցվածք և աշխատավարձ'!$I$51:$I$52="Կրիտիկական")) -> 8179200 | H23: Համալրվածները + կրիտիկական թափուրները | K23: Ֆիքս հարկերով × (համալրված + կրիտիկական թափուր)
B24: ԼՐԻՎ ՀԱՄԱԼՐՎԵԼԻՍ | E24: ='Կառուցվածք և աշխատավարձ'!$AA$55 -> 15695333 | H24: Բոլոր հաստիքները, բազային բոնուսով | K24: Բազային սցենար 100–119%
B25: ՀԱՋՈՐԴ ՏԱՐԻ | E25: ='Կառուցվածք և աշխատավարձ'!$AA$55*12 -> 188344000 | H25: Լրիվ համալրված, 12 ամիս | K25: Լրիվ համալրված × 12
B27: ԲԱԺԻՆՆԵՐ
B29: Բաժին | D29: Հաստիք | E29: Համալրված | F29: Թափուր | G29: Լրացված % | H29: Ֆիքս՝ մաքուր | I29: Ֆիքս՝ հարկերով | J29: Բազային՝ մաքուր | K29: Բազային՝ հարկերով | L29: Առավելագույն՝ մաքուր | M29: Առավելագույն՝ հարկերով
B30: Կոմերցիոն (առանց D2D) | D30: ='Կառուցվածք և աշխատավարձ'!$F$18 -> 13 | E30: ='Կառուցվածք և աշխատավարձ'!$G$18 -> 6 | F30: ='Կառուցվածք և աշխատավարձ'!$H$18 -> 7 | G30: ='Կառուցվածք և աշխատավարձ'!$G$18/'Կառուցվածք և աշխատավարձ'!$F$18 -> 0.46153846 | H30: ='Կառուցվածք և աշխատավարձ'!$P$18 -> 1960000 | I30: ='Կառուցվածք և աշխատավարձ'!$Q$18 -> 2721866.7 | J30: ='Կառուցվածք և աշխատավարձ'!$V$18 -> 2646000 | K30: ='Կառուցվածք և աշխատավարձ'!$AA$18 -> 3623733.3 | L30: ='Կառուցվածք և աշխատավարձ'!$W$18 -> 2940000 | M30: ='Կառուցվածք և աշխատավարձ'!$AB$18 -> 4028533.3
B31: D2D գործակալ (առանձին հոդված) | D31: ='Կառուցվածք և աշխատավարձ'!$F$17 -> 6 | E31: ='Կառուցվածք և աշխատավարձ'!$G$17 -> 0 | F31: ='Կառուցվածք և աշխատավարձ'!$H$17 -> 6 | G31: ='Կառուցվածք և աշխատավարձ'!$G$17/'Կառուցվածք և աշխատավարձ'!$F$17 -> 0 | H31: ='Կառուցվածք և աշխատավարձ'!$P$17 -> 420000 | I31: ='Կառուցվածք և աշխատավարձ'!$Q$17 -> 606400 | J31: ='Կառուցվածք և աշխատավարձ'!$V$17 -> 900000 | K31: ='Կառուցվածք և աշխատավարձ'!$AA$17 -> 1246400 | L31: ='Կառուցվածք և աշխատավարձ'!$W$17 -> 996000 | M31: ='Կառուցվածք և աշխատավարձ'!$AB$17 -> 1374400
B32: Տեխնիկական | D32: ='Կառուցվածք և աշխատավարձ'!$F$36 -> 22 | E32: ='Կառուցվածք և աշխատավարձ'!$G$36 -> 13 | F32: ='Կառուցվածք և աշխատավարձ'!$H$36 -> 9 | G32: ='Կառուցվածք և աշխատավարձ'!$G$36/'Կառուցվածք և աշխատավարձ'!$F$36 -> 0.59090909 | H32: ='Կառուցվածք և աշխատավարձ'!$P$36 -> 4010000 | I32: ='Կառուցվածք և աշխատավարձ'!$Q$36 -> 5524800 | J32: ='Կառուցվածք և աշխատավարձ'!$V$36 -> 5413500 | K32: ='Կառուցվածք և աշխատավարձ'!$AA$36 -> 7388133.3 | L32: ='Կառուցվածք և աշխատավարձ'!$W$36 -> 6015000 | M32: ='Կառուցվածք և աշխատավարձ'!$AB$36 -> 8198133.3
B33: Հաճախորդների սպասարկում | D33: ='Կառուցվածք և աշխատավարձ'!$F$43 -> 9 | E33: ='Կառուցվածք և աշխատավարձ'!$G$43 -> 5 | F33: ='Կառուցվածք և աշխատավարձ'!$H$43 -> 4 | G33: ='Կառուցվածք և աշխատավարձ'!$G$43/'Կառուցվածք և աշխատավարձ'!$F$43 -> 0.55555556 | H33: ='Կառուցվածք և աշխատավարձ'!$P$43 -> 1320000 | I33: ='Կառուցվածք և աշխատավարձ'!$Q$43 -> 1837600 | J33: ='Կառուցվածք և աշխատավարձ'!$V$43 -> 1782000 | K33: ='Կառուցվածք և աշխատավարձ'!$AA$43 -> 2453600 | L33: ='Կառուցվածք և աշխատավարձ'!$W$43 -> 1980000 | M33: ='Կառուցվածք և աշխատավարձ'!$AB$43 -> 2717600
B34: Բիլինգ և եկամուտ | D34: ='Կառուցվածք և աշխատավարձ'!$F$48 -> 2 | E34: ='Կառուցվածք և աշխատավարձ'!$G$48 -> 1 | F34: ='Կառուցվածք և աշխատավարձ'!$H$48 -> 1 | G34: ='Կառուցվածք և աշխատավարձ'!$G$48/'Կառուցվածք և աշխատավարձ'!$F$48 -> 0.5 | H34: ='Կառուցվածք և աշխատավարձ'!$P$48 -> 450000 | I34: ='Կառուցվածք և աշխատավարձ'!$Q$48 -> 623466.67 | J34: ='Կառուցվածք և աշխատավարձ'!$V$48 -> 607500 | K34: ='Կառուցվածք և աշխատավարձ'!$AA$48 -> 833466.67 | L34: ='Կառուցվածք և աշխատավարձ'!$W$48 -> 675000 | M34: ='Կառուցվածք և աշխատավարձ'!$AB$48 -> 923466.67
B35: ԱՁ պայմանագրեր (հաստիք չէ) | D35: ='Կառուցվածք և աշխատավարձ'!$F$53 -> 2 | E35: ='Կառուցվածք և աշխատավարձ'!$G$53 -> 0 | F35: ='Կառուցվածք և աշխատավարձ'!$H$53 -> 2 | G35: ='Կառուցվածք և աշխատավարձ'!$G$53/'Կառուցվածք և աշխատավարձ'!$F$53 -> 0 | H35: ='Կառուցվածք և աշխատավարձ'!$P$53 -> 150000 | I35: ='Կառուցվածք և աշխատավարձ'!$Q$53 -> 150000 | J35: ='Կառուցվածք և աշխատավարձ'!$V$53 -> 150000 | K35: ='Կառուցվածք և աշխատավարձ'!$AA$53 -> 150000 | L35: ='Կառուցվածք և աշխատավարձ'!$W$53 -> 150000 | M35: ='Կառուցվածք և աշխատավարձ'!$AB$53 -> 150000
B36: ԸՆԴԱՄԵՆԸ | D36: ='Կառուցվածք և աշխատավարձ'!$F$55 -> 54 | E36: ='Կառուցվածք և աշխատավարձ'!$G$55 -> 25 | F36: ='Կառուցվածք և աշխատավարձ'!$H$55 -> 29 | G36: ='Կառուցվածք և աշխատավարձ'!$G$55/'Կառուցվածք և աշխատավարձ'!$F$55 -> 0.46296296 | H36: ='Կառուցվածք և աշխատավարձ'!$P$55 -> 8310000 | I36: ='Կառուցվածք և աշխատավարձ'!$Q$55 -> 11464133 | J36: ='Կառուցվածք և աշխատավարձ'!$V$55 -> 11499000 | K36: ='Կառուցվածք և աշխատավարձ'!$AA$55 -> 15695333 | L36: ='Կառուցվածք և աշխատավարձ'!$W$55 -> 12756000 | M36: ='Կառուցվածք և աշխատավարձ'!$AB$55 -> 17392133
B38: ՎՃԱՐՄԱՆ ՄՈԴԵԼՆԵՐ
B40: Մոդել | D40: Հաստիք | E40: Ո՞ւմ վրա | G40: Ինչպե՞ս է վճարվում
B41: ='Մոդելներ և պարտադիր վճարներ'!$B$42 -> Ա. Ֆիքս + KPI բոնուս | D41: ='Մոդելներ և պարտադիր վճարներ'!$D$42 -> 46 | E41: ='Մոդելներ և պարտադիր վճարներ'!$C$42 -> Բոլոր պաշտոնները, բացի Բ և Գ-ից | G41: ='Մոդելներ և պարտադիր վճարներ'!$E$42 -> Ֆիքս + (Ֆիքս × բոնուսի աստիճան)։ Աստիճանը՝ KPI-ի կշռված կատարմամբ։
B42: ='Մոդելներ և պարտադիր վճարներ'!$B$43 -> Բ. D2D | D42: ='Մոդելներ և պարտադիր վճարներ'!$D$43 -> 6 | E42: ='Մոդելներ և պարտադիր վճարներ'!$C$43 -> D2D գործակալ | G42: ='Մոդելներ և պարտադիր վճարներ'!$E$43 -> Ֆիքսը՝ միայն պլանի 80%-ը հատելու դեպքում՝ գումարած վաճառած սակագների 100%-ը։ Շեմից ցածր՝ միայն սակագինը։ Առաստաղ չկա։
B43: ='Մոդելներ և պարտադիր վճարներ'!$B$44 -> Գ. ԱՁ / Outsourcing | D43: ='Մոդելներ և պարտադիր վճարներ'!$D$44 -> 2 | E43: ='Մոդելներ և պարտադիր վճարներ'!$C$44 -> Հավաքագրող, Իրավաբան | G43: ='Մոդելներ և պարտադիր վճարներ'!$E$44 -> Միայն հաշիվ-ապրանքագրի գումարը։ Ընկերությունը հարկ չի պահում։
B45: ՊԱՐՏԱԴԻՐ ՎՃԱՐՆԵՐ ԵՎ ՀԱՄԱԼՐՄԱՆ ԱՌԱՋՆԱՀԵՐԹՈՒԹՅՈՒՆ
B47: Եկամտահարկ | D47: Սոցիալական վճար | F47: Դրոշմանիշային | H47: Ապահովագրություն | J47: Զուտից հարկերով գործակից
B48: ='Մոդելներ և պարտադիր վճարներ'!$C$57 -> 0.2 | D48: ='Մոդելներ և պարտադիր վճարներ'!$C$58 -> 0.05 | F48: =TEXT('Մոդելներ և պարտադիր վճարներ'!$D$67,"#,##0")&" – "&TEXT('Մոդելներ և պարտադիր վճարներ'!$D$71,"#,##0") -> 1,000 – 15,000 | H48: =TEXT('Մոդելներ և պարտադիր վճարներ'!$E$69,"#,##0")&" / "&TEXT('Մոդելներ և պարտադիր վճարներ'!$E$71,"#,##0") -> 4,800 / 10,800 | J48: ='Մոդելներ և պարտադիր վճարներ'!$C$59 -> 1.3333333
B50: Կրիտիկական | D50: Կարևոր | F50: Կարող է սպասել | H50: Համալրված | J50: Ընդամենը մարդ
B51: =SUMIFS('Կառուցվածք և աշխատավարձ'!$H$7:$H$47,'Կառուցվածք և աշխատավարձ'!$I$7:$I$47,"Կրիտիկական") -> 13 | D51: =SUMIFS('Կառուցվածք և աշխատավարձ'!$H$7:$H$47,'Կառուցվածք և աշխատավարձ'!$I$7:$I$47,"Կարևոր") -> 6 | F51: =SUMIFS('Կառուցվածք և աշխատավարձ'!$H$7:$H$47,'Կառուցվածք և աշխատավարձ'!$I$7:$I$47,"Կարող է սպասել") -> 8 | H51: ='Կառուցվածք և աշխատավարձ'!$G$55-'Կառուցվածք և աշխատավարձ'!$G$53 -> 25 | J51: =B51+D51+F51+H51 -> 52
B55: ԲՈՆՈՒՍԱՅԻՆ ՄԵԽԱՆԻԿԱ
B57: KPI ՉԱՓՈՒՄՆԵՐ | E57: ԲՈՆՈՒՍԻ ԱՍՏԻՃԱՆՆԵՐ | H57: ԲՈՆՈՒՍԻ ՖՈՆԴ՝ ԲԱԶԱՅԻՆ | K57: ԲՈՆՈՒՍԻ ՖՈՆԴ՝ ԱՌԱՎԵԼԱԳՈՒՅՆ
B58: =COUNTA(KPI!$E$8:$E$107)-COUNTIF(KPI!$E$8:$E$107,"KPI չի կիրառվում") -> 97 | E58: =TEXT('Մոդելներ և պարտադիր վճարներ'!$D$7,"0%")&" / "&TEXT('Մոդելներ և պարտադիր վճարներ'!$D$8,"0%")&" / "&TEXT('Մոդելներ և պարտադիր վճարներ'!$D$9,"0%")&" / "&TEXT('Մոդելներ և պարտադիր վճարներ'!$D$10,"0%")&" / "&TEXT('Մոդելներ և պարտադիր վճարներ'!$D$11,"0%") -> 0% / 15% / 25% / 35% / 50% | H58: ='Կառուցվածք և աշխատավարձ'!$AA$55-'Կառուցվածք և աշխատավարձ'!$Q$55 -> 4231200 | K58: ='Կառուցվածք և աշխատավարձ'!$AB$55-'Կառուցվածք և աշխատավարձ'!$Q$55 -> 5928000
...

Sheet Կառուցվածք և աշխատավարձ
B2: Բաժինների միասնական կառուցվածք, աշխատավարձային ամփոփում և բոնուսային համակարգի նախագիծ
B4: Բաժին | C4: Խումբ | D4: Հաստիք | E4: Դրույք | F4: Քանակ | G4: Համալրված | H4: Թափուր | I4: Համալրման առաջնահերթություն | J4: Ֆիքսված աշխատավարձ առանց հարկերի | K4: ="Եկամտահարկ՝ "&TEXT('Մոդելներ և պարտադիր վճարներ'!$C$57,"0%") -> Եկամտահարկ՝ 20% | L4: ="Սոցիալական վճար՝ "&TEXT('Մոդելներ և պարտադիր վճարներ'!$C$58,"0%") -> Սոցիալական վճար՝ 5% | M4: ="Դրոշմանիշային վճար՝ "&TEXT('Մոդելներ և պարտադիր վճարներ'!$D$67,"#,##0")&"–"&TEXT('Մոդելներ և պարտադիր վճարներ'!$D$71,"#,##0")&" (ըստ սանդղակի)" -> Դրոշմանիշային վճար՝ 1,000–15,000 (ըստ սանդղակի) | N4: ="Առողջության ապահովագրություն՝ "&TEXT('Մոդելներ և պարտադիր վճարներ'!$E$69,"#,##0")&" / "&TEXT('Մոդելներ և պարտադիր վճարներ'!$E$71,"#,##0")&" (ըստ սանդղակի)" -> Առողջության ապահովագրություն՝ 4,800 / 10,800 (ըստ սանդղակի) | O4: ="Ֆիքսված աշխատավարձ հարկերը ներառյալ (× "&TEXT('Մոդելներ և պարտադիր վճարներ'!$C$59,"0.0000")&")" -> Ֆիքսված աշխատավարձ հարկերը ներառյալ (× 1.3333) | P4: Ֆիքսված աշխատավարձ առանց հարկերի ըստ հաստիքների քանակի | Q4: Ֆիքսված աշխատավարձ հարկերը ներառյալ ըստ հաստիքների քանակի | R4: Վճարման մոդել | S4: ="Ընդամենը մաքուր՝ < 80% (բոնուս +"&TEXT('Մոդելներ և պարտադիր վճարներ'!$D$7,"0%")&")" -> Ընդամենը մաքուր՝ < 80% (բոնուս +0%) | T4: ="Ընդամենը մաքուր՝ 80–89% (բոնուս +"&TEXT('Մոդելներ և պարտադիր վճարներ'!$D$8,"0%")&")" -> Ընդամենը մաքուր՝ 80–89% (բոնուս +15%) | U4: ="Ընդամենը մաքուր՝ 90–99% (բոնուս +"&TEXT('Մոդելներ և պարտադիր վճարներ'!$D$9,"0%")&")" -> Ընդամենը մաքուր՝ 90–99% (բոնուս +25%) | V4: ="Ընդամենը մաքուր՝ 100–119% (բոնուս +"&TEXT('Մոդելներ և պարտադիր վճարներ'!$D$10,"0%")&")" -> Ընդամենը մաքուր՝ 100–119% (բոնուս +35%) | W4: ="Ընդամենը մաքուր՝ ≥ 120% (բոնուս +"&TEXT('Մոդելներ և պարտադիր վճարներ'!$D$11,"0%")&")" -> Ընդամենը մաքուր՝ ≥ 120% (բոնուս +50%) | X4: ="Ընդամենը հարկերով՝ < 80% (բոնուս +"&TEXT('Մոդելներ և պարտադիր վճարներ'!$D$7,"0%")&")" -> Ընդամենը հարկերով՝ < 80% (բոնուս +0%) | Y4: ="Ընդամենը հարկերով՝ 80–89% (բոնուս +"&TEXT('Մոդելներ և պարտադիր վճարներ'!$D$8,"0%")&")" -> Ընդամենը հարկերով՝ 80–89% (բոնուս +15%) | Z4: ="Ընդամենը հարկերով՝ 90–99% (բոնուս +"&TEXT('Մոդելներ և պարտադիր վճարներ'!$D$9,"0%")&")" -> Ընդամենը հարկերով՝ 90–99% (բոնուս +25%) | AA4: ="Ընդամենը հարկերով՝ 100–119% (բոնուս +"&TEXT('Մոդելներ և պարտադիր վճարներ'!$D$10,"0%")&")" -> Ընդամենը հարկերով՝ 100–119% (բոնուս +35%) | AB4: ="Ընդամենը հարկերով՝ ≥ 120% (բոնուս +"&TEXT('Մոդելներ և պարտադիր վճարներ'!$D$11,"0%")&")" -> Ընդամենը հարկերով՝ ≥ 120% (բոնուս +50%) | AC4: Բոնուսի կանոն | AD4: Անմիջական ղեկավար
B6: ԿՈՄԵՐՑԻՈՆ
B7: Կոմերցիոն | C7: Վաճառք | D7: Վաճառքի ղեկավար | E7: 1 | F7: 1 | G7: 1 | H7: =$F7-$G7 -> 0 | I7: Համալրված | J7: 350000 | K7: =IF(COUNTIFS('Մոդելներ և պարտադիր վճարներ'!$B$35:$B$37,$D7,'Մոդելներ և պարտադիր վճարներ'!$C$35:$C$37,"ԱՁ")>0,0,$O7*'Մոդելներ և պարտադիր վճարներ'!$C$57) -> 96480 | L7: =IF(COUNTIFS('Մոդելներ և պարտադիր վճարներ'!$B$35:$B$37,$D7,'Մոդելներ և պարտադիր վճարներ'!$C$35:$C$37,"ԱՁ")>0,0,$O7*'Մոդելներ և պարտադիր վճարներ'!$C$58) -> 24120 | M7: =IF(COUNTIFS('Մոդելներ և պարտադիր վճարներ'!$B$35:$B$37,$D7,'Մոդելներ և պարտադիր վճարներ'!$C$35:$C$37,"ԱՁ")>0,0,INDEX('Մոդելներ և պարտադիր վճարներ'!$D$67:$D$71,IFERROR(MATCH(IFERROR(INDEX('Մոդելներ և պարտադիր վճարներ'!$D$35:$D$37,MATCH($D7,'Մոդելներ և պարտադիր վճարներ'!$B$35:$B$37,0)),$J7*(1+'Մոդելներ և պարտադիր վճարներ'!$C$60)),'Մոդելներ և պարտադիր վճարներ'!$F$67:$F$71,1)+1,1))) -> 1000 | N7: =IF(COUNTIFS('Մոդելներ և պարտադիր վճարներ'!$B$35:$B$37,$D7,'Մոդելներ և պարտադիր վճարներ'!$C$35:$C$37,"ԱՁ")>0,0,INDEX('Մոդելներ և պարտադիր վճարներ'!$E$67:$E$71,IFERROR(MATCH(IFERROR(INDEX('Մոդելներ և պարտադիր վճարներ'!$D$35:$D$37,MATCH($D7,'Մոդելներ և պարտադիր վճարներ'!$B$35:$B$37,0)),$J7*(1+'Մոդելներ և պարտադիր վճարներ'!$C$60)),'Մոդելներ և պարտադիր վճարներ'!$F$67:$F$71,1)+1,1))) -> 10800 | O7: =IF(COUNTIFS('Մոդելներ և պարտադիր վճարներ'!$B$35:$B$37,$D7,'Մոդելներ և պարտադիր վճարներ'!$C$35:$C$37,"ԱՁ")>0,$J7,($J7+$M7+$N7)*'Մոդելներ և պարտադիր վճարներ'!$C$59) -> 482400 | P7: =F7*$J7 -> 350000 | Q7: =O7*F7 -> 482400 | R7: =IF(COUNTIFS('Մոդելներ և պարտադիր վճարներ'!$B$35:$B$37,$D7,'Մոդելներ և պարտադիր վճարներ'!$C$35:$C$37,"ԱՁ")>0,"Գ. ԱՁ",IF(COUNTIFS('Մոդելներ և պարտադիր վճարներ'!$B$35:$B$37,$D7,'Մոդելներ և պարտադիր վճարներ'!$C$35:$C$37,"D2D")>0,"Բ. D2D","Ա. Ֆիքս + KPI բոնուս")) -> Ա. Ֆիքս + KPI բոնուս | S7: =IF(COUNTIFS('Մոդելներ և պարտադիր վճարներ'!$B$35:$B$37,$D7,'Մոդելներ և պարտադիր վճարներ'!$C$35:$C$37,"ԱՁ")>0,$J7,IF(COUNTIFS('Մոդելներ և պարտադիր վճարներ'!$B$35:$B$37,$D7,'Մոդելներ և պարտադիր վճարներ'!$C$35:$C$37,"D2D")>0,'Մոդելներ և պարտադիր վճարներ'!$G$26,$J7*(1+'Մոդելներ և պարտադիր վճարներ'!$D$7))) -> 350000 | T7: =IF(COUNTIFS('Մոդելներ և պարտադիր վճարներ'!$B$35:$B$37,$D7,'Մոդելներ և պարտադիր վճարներ'!$C$35:$C$37,"ԱՁ")>0,$J7,IF(COUNTIFS('Մոդելներ և պարտադիր վճարներ'!$B$35:$B$37,$D7,'Մոդելներ և պարտադիր վճարներ'!$C$35:$C$37,"D2D")>0,'Մոդելներ և պարտադիր վճարներ'!$G$27,$J7*(1+'Մոդելներ և պարտադիր վճարներ'!$D$8))) -> 402500 | U7: =IF(COUNTIFS('Մոդելներ և պարտադիր վճարներ'!$B$35:$B$37,$D7,'Մոդելներ և պարտադիր վճարներ'!$C$35:$C$37,"ԱՁ")>0,$J7,IF(COUNTIFS('Մոդելներ և պարտադիր վճարներ'!$B$35:$B$37,$D7,'Մոդելներ և պարտադիր վճարներ'!$C$35:$C$37,"D2D")>0,'Մոդելներ և պարտադիր վճարներ'!$G$28,$J7*(1+'Մոդելներ և պարտադիր վճարներ'!$D$9))) -> 437500 | V7: =IF(COUNTIFS('Մոդելներ և պարտադիր վճարներ'!$B$35:$B$37,$D7,'Մոդելներ և պարտադիր վճարներ'!$C$35:$C$37,"ԱՁ")>0,$J7,IF(COUNTIFS('Մոդելներ և պարտադիր վճարներ'!$B$35:$B$37,$D7,'Մոդելներ և պարտադիր վճարներ'!$C$35:$C$37,"D2D")>0,'Մոդելներ և պարտադիր վճարներ'!$G$29,$J7*(1+'Մոդելներ և պարտադիր վճարներ'!$D$10))) -> 472500 | W7: =IF(COUNTIFS('Մոդելներ և պարտադիր վճարներ'!$B$35:$B$37,$D7,'Մոդելներ և պարտադիր վճարներ'!$C$35:$C$37,"ԱՁ")>0,$J7,IF(COUNTIFS('Մոդելներ և պարտադիր վճարներ'!$B$35:$B$37,$D7,'Մոդելներ և պարտադիր վճարներ'!$C$35:$C$37,"D2D")>0,'Մոդելներ և պարտադիր վճարներ'!$G$30,$J7*(1+'Մոդելներ և պարտադիր վճարներ'!$D$11))) -> 525000 | X7: =IF(COUNTIFS('Մոդելներ և պարտադիր վճարներ'!$B$35:$B$37,$D7,'Մոդելներ և պարտադիր վճարներ'!$C$35:$C$37,"ԱՁ")>0,$J7,($S7+INDEX('Մոդելներ և պարտադիր վճարներ'!$D$67:$D$71,IFERROR(MATCH($S7,'Մոդելներ և պարտադիր վճարներ'!$F$67:$F$71,1)+1,1))+INDEX('Մոդելներ և պարտադիր վճարներ'!$E$67:$E$71,IFERROR(MATCH($S7,'Մոդելներ և պարտադիր վճարներ'!$F$67:$F$71,1)+1,1)))*'Մոդելներ և պարտադիր վճարներ'!$C$59) -> 474400 | Y7: =IF(COUNTIFS('Մոդելներ և պարտադիր վճարներ'!$B$35:$B$37,$D7,'Մոդելներ և պարտադիր վճարներ'!$C$35:$C$37,"ԱՁ")>0,$J7,($T7+INDEX('Մոդելներ և պարտադիր վճարներ'!$D$67:$D$71,IFERROR(MATCH($T7,'Մոդելներ և պարտադիր վճարներ'!$F$67:$F$71,1)+1,1))+INDEX('Մոդելներ և պարտադիր վճարներ'!$E$67:$E$71,IFERROR(MATCH($T7,'Մոդելներ և պարտադիր վճարներ'!$F$67:$F$71,1)+1,1)))*'Մոդելներ և պարտադիր վճարներ'!$C$59) -> 552400 | Z7: =IF(COUNTIFS('Մոդելներ և պարտադիր վճարներ'!$B$35:$B$37,$D7,'Մոդելներ և պարտադիր վճարներ'!$C$35:$C$37,"ԱՁ")>0,$J7,($U7+INDEX('Մոդելներ և պարտադիր վճարներ'!$D$67:$D$71,IFERROR(MATCH($U7,'Մոդելներ և պարտադիր վճարներ'!$F$67:$F$71,1)+1,1))+INDEX('Մոդելներ և պարտադիր վճարներ'!$E$67:$E$71,IFERROR(MATCH($U7,'Մոդելներ և պարտադիր վճարներ'!$F$67:$F$71,1)+1,1)))*'Մոդելներ և պարտադիր վճարներ'!$C$59) -> 599066.67 | AA7: =IF(COUNTIFS('Մոդելներ և պարտադիր վճարներ'!$B$35:$B$37,$D7,'Մոդելներ և պարտադիր վճարներ'!$C$35:$C$37,"ԱՁ")>0,$J7,($V7+INDEX('Մոդելներ և պարտադիր վճարներ'!$D$67:$D$71,IFERROR(MATCH($V7,'Մոդելներ և պարտադիր վճարներ'!$F$67:$F$71,1)+1,1))+INDEX('Մոդելներ և պարտադիր վճարներ'!$E$67:$E$71,IFERROR(MATCH($V7,'Մոդելներ և պարտադիր վճարներ'!$F$67:$F$71,1)+1,1)))*'Մոդելներ և պարտադիր վճարներ'!$C$59) -> 645733.33 | AB7: =IF(COUNTIFS('Մոդելներ և պարտադիր վճարներ'!$B$35:$B$37,$D7,'Մոդելներ և պարտադիր վճարներ'!$C$35:$C$37,"ԱՁ")>0,$J7,($W7+INDEX('Մոդելներ և պարտադիր վճարներ'!$D$67:$D$71,IFERROR(MATCH($W7,'Մոդելներ և պարտադիր վճարներ'!$F$67:$F$71,1)+1,1))+INDEX('Մոդելներ և պարտադիր վճարներ'!$E$67:$E$71,IFERROR(MATCH($W7,'Մոդելներ և պարտադիր վճարներ'!$F$67:$F$71,1)+1,1)))*'Մոդելներ և պարտադիր վճարներ'!$C$59) -> 715733.33 | AC7: =IF(COUNTIFS('Մոդելներ և պարտադիր վճարներ'!$B$35:$B$37,$D7,'Մոդելներ և պարտադիր վճարներ'!$C$35:$C$37,"ԱՁ")>0,"Աստիճաններ չեն կիրառվում — հաշիվ-ապրանքագիր",IF(COUNTIFS('Մոդելներ և պարտադիր վճարներ'!$B$35:$B$37,$D7,'Մոդելներ և պարտադիր վճարներ'!$C$35:$C$37,"D2D")>0,"Աստիճաններ չեն կիրառվում — տես D2D բաժինը","Ֆիքս × (1 + աստիճանի %)")) -> Ֆիքս × (1 + աստիճանի %) | AD7: Վաճառքի և գործառնական ղեկավար
B8: Կոմերցիոն | C8: Վաճառք | D8: Վաճառքի և սպասարկման ավագ մասնագետ | E8: 1 | F8: 3 | G8: 3 | H8: =$F8-$G8 -> 0 | I8: Համալրված | J8: 150000 | K8: =IF(COUNTIFS('Մոդելներ և պարտադիր վճարներ'!$B$35:$B$37,$D8,'Մոդելներ և պարտադիր վճարներ'!$C$35:$C$37,"ԱՁ")>0,0,$O8*'Մոդելներ և պարտադիր վճարներ'!$C$57) -> 41546.667 | L8: =IF(COUNTIFS('Մոդելներ և պարտադիր վճարներ'!$B$35:$B$37,$D8,'Մոդելներ և պարտադիր վճարներ'!$C$35:$C$37,"ԱՁ")>0,0,$O8*'Մոդելներ և պարտադիր վճարներ'!$C$58) -> 10386.667 | M8: =IF(COUNTIFS('Մոդելներ և պարտադիր վճարներ'!$B$35:$B$37,$D8,'Մոդելներ և պարտադիր վճարներ'!$C$35:$C$37,"ԱՁ")>0,0,INDEX('Մոդելներ և պարտադիր վճարներ'!$D$67:$D$71,IFERROR(MATCH(IFERROR(INDEX('Մոդելներ և պարտադիր վճարներ'!$D$35:$D$37,MATCH($D8,'Մոդելներ և պարտադիր վճարներ'!$B$35:$B$37,0)),$J8*(1+'Մոդելներ և պարտադիր վճարներ'!$C$60)),'Մոդելներ և պարտադիր վճարներ'!$F$67:$F$71,1)+1,1))) -> 1000 | N8: =IF(COUNTIFS('Մոդելներ և պարտադիր վճարներ'!$B$35:$B$37,$D8,'Մոդելներ և պարտադիր վճարներ'!$C$35:$C$37,"ԱՁ")>0,0,INDEX('Մոդելներ և պարտադիր վճարներ'!$E$67:$E$71,IFERROR(MATCH(IFERROR(INDEX('Մոդելներ և պարտադիր վճարներ'!$D$35:$D$37,MATCH($D8,'Մոդելներ և պարտադիր վճարներ'!$B$35:$B$37,0)),$J8*(1+'Մոդելներ և պարտադիր վճարներ'!$C$60)),'Մոդելներ և պարտադիր վճարներ'!$F$67:$F$71,1)+1,1))) -> 4800 | O8: =IF(COUNTIFS('Մոդելներ և պարտադիր վճարներ'!$B$35:$B$37,$D8,'Մոդելներ և պարտադիր վճարներ'!$C$35:$C$37,"ԱՁ")>0,$J8,($J8+$M8+$N8)*'Մոդելներ և պարտադիր վճարներ'!$C$59) -> 207733.33 | P8: =F8*$J8 -> 450000 | Q8: =O8*F8 -> 623200 | R8: =IF(COUNTIFS('Մոդելներ և պարտադիր վճարներ'!$B$35:$B$37,$D8,'Մոդելներ և պարտադիր վճարներ'!$C$35:$C$37,"ԱՁ")>0,"Գ. ԱՁ",IF(COUNTIFS('Մոդելներ և պարտադիր վճարներ'!$B$35:$B$37,$D8,'Մոդելներ և պարտադիր վճարներ'!$C$35:$C$37,"D2D")>0,"Բ. D2D","Ա. Ֆիքս + KPI բոնուս")) -> Ա. Ֆիքս + KPI բոնուս | S8: =IF(COUNTIFS('Մոդելներ և պարտադիր վճարներ'!$B$35:$B$37,$D8,'Մոդելներ և պարտադիր վճարներ'!$C$35:$C$37,"ԱՁ")>0,$J8,IF(COUNTIFS('Մոդելներ և պարտադիր վճարներ'!$B$35:$B$37,$D8,'Մոդելներ և պարտադիր վճարներ'!$C$35:$C$37,"D2D")>0,'Մոդելներ և պարտադիր վճարներ'!$G$26,$J8*(1+'Մոդելներ և պարտադիր վճարներ'!$D$7))) -> 150000 | T8: =IF(COUNTIFS('Մոդելներ և պարտադիր վճարներ'!$B$35:$B$37,$D8,'Մոդելներ և պարտադիր վճարներ'!$C$35:$C$37,"ԱՁ")>0,$J8,IF(COUNTIFS('Մոդելներ և պարտադիր վճարներ'!$B$35:$B$37,$D8,'Մոդելներ և պարտադիր վճարներ'!$C$35:$C$37,"D2D")>0,'Մոդելներ և պարտադիր վճարներ'!$G$27,$J8*(1+'Մոդելներ և պարտադիր վճարներ'!$D$8))) -> 172500 | U8: =IF(COUNTIFS('Մոդելներ և պարտադիր վճարներ'!$B$35:$B$37,$D8,'Մոդելներ և պարտադիր վճարներ'!$C$35:$C$37,"ԱՁ")>0,$J8,IF(COUNTIFS('Մոդելներ և պարտադիր վճարներ'!$B$35:$B$37,$D8,'Մոդելներ և պարտադիր վճարներ'!$C$35:$C$37,"D2D")>0,'Մոդելներ և պարտադիր վճարներ'!$G$28,$J8*(1+'Մոդելներ և պարտադիր վճարներ'!$D$9))) -> 187500 | V8: =IF(COUNTIFS('Մոդելներ և պարտադիր վճարներ'!$B$35:$B$37,$D8,'Մոդելներ և պարտադիր վճարներ'!$C$35:$C$37,"ԱՁ")>0,$J8,IF(COUNTIFS('Մոդելներ և պարտադիր վճարներ'!$B$35:$B$37,$D8,'Մոդելներ և պարտադիր վճարներ'!$C$35:$C$37,"D2D")>0,'Մոդելներ և պարտադիր վճարներ'!$G$29,$J8*(1+'Մոդելներ և պարտադիր վճարներ'!$D$10))) -> 202500 | W8: =IF(COUNTIFS('Մոդելներ և պարտադիր վճարներ'!$B$35:$B$37,$D8,'Մոդելներ և պարտադիր վճարներ'!$C$35:$C$37,"ԱՁ")>0,$J8,IF(COUNTIFS('Մոդելներ և պարտադիր վճարներ'!$B$35:$B$37,$D8,'Մոդելներ և պարտադիր վճարներ'!$C$35:$C$37,"D2D")>0,'Մոդելներ և պարտադիր վճարներ'!$G$30,$J8*(1+'Մոդելներ և պարտադիր վճարներ'!$D$11))) -> 225000 | X8: =IF(COUNTIFS('Մոդելներ և պարտադիր վճարներ'!$B$35:$B$37,$D8,'Մոդելներ և պարտադիր վճարներ'!$C$35:$C$37,"ԱՁ")>0,$J8,($S8+INDEX('Մոդելներ և պարտադիր վճարներ'!$D$67:$D$71,IFERROR(MATCH($S8,'Մոդելներ և պարտադիր վճարներ'!$F$67:$F$71,1)+1,1))+INDEX('Մոդելներ և պարտադիր վճարներ'!$E$67:$E$71,IFERROR(MATCH($S8,'Մոդելներ և պարտադիր վճարներ'!$F$67:$F$71,1)+1,1)))*'Մոդելներ և պարտադիր վճարներ'!$C$59) -> 207733.33 | Y8: =IF(COUNTIFS('Մոդելներ և պարտադիր վճարներ'!$B$35:$B$37,$D8,'Մոդելներ և պարտադիր վճարներ'!$C$35:$C$37,"ԱՁ")>0,$J8,($T8+INDEX('Մոդելներ և պարտադիր վճարներ'!$D$67:$D$71,IFERROR(MATCH($T8,'Մոդելներ և պարտադիր վճարներ'!$F$67:$F$71,1)+1,1))+INDEX('Մոդելներ և պարտադիր վճարներ'!$E$67:$E$71,IFERROR(MATCH($T8,'Մոդելներ և պարտադիր վճարներ'!$F$67:$F$71,1)+1,1)))*'Մոդելներ և պարտադիր վճարներ'!$C$59) -> 237733.33 | Z8: =IF(COUNTIFS('Մոդելներ և պարտադիր վճարներ'!$B$35:$B$37,$D8,'Մոդելներ և պարտադիր վճարներ'!$C$35:$C$37,"ԱՁ")>0,$J8,($U8+INDEX('Մոդելներ և պարտադիր վճարներ'!$D$67:$D$71,IFERROR(MATCH($U8,'Մոդելներ և պարտադիր վճարներ'!$F$67:$F$71,1)+1,1))+INDEX('Մոդելներ և պարտադիր վճարներ'!$E$67:$E$71,IFERROR(MATCH($U8,'Մոդելներ և պարտադիր վճարներ'!$F$67:$F$71,1)+1,1)))*'Մոդելներ և պարտադիր վճարներ'!$C$59) -> 257733.33 | AA8: =IF(COUNTIFS('Մոդելներ և պարտադիր վճարներ'!$B$35:$B$37,$D8,'Մոդելներ և պարտադիր վճարներ'!$C$35:$C$37,"ԱՁ")>0,$J8,($V8+INDEX('Մոդելներ և պարտադիր վճարներ'!$D$67:$D$71,IFERROR(MATCH($V8,'Մոդելներ և պարտադիր վճարներ'!$F$67:$F$71,1)+1,1))+INDEX('Մոդելներ և պարտադիր վճարներ'!$E$67:$E$71,IFERROR(MATCH($V8,'Մոդելներ և պարտադիր վճարներ'!$F$67:$F$71,1)+1,1)))*'Մոդելներ և պարտադիր վճարներ'!$C$59) -> 277733.33 | AB8: =IF(COUNTIFS('Մոդելներ և պարտադիր վճարներ'!$B$35:$B$37,$D8,'Մոդելներ և պարտադիր վճարներ'!$C$35:$C$37,"ԱՁ")>0,$J8,($W8+INDEX('Մոդելներ և պարտադիր վճարներ'!$D$67:$D$71,IFERROR(MATCH($W8,'Մոդելներ և պարտադիր վճարներ'!$F$67:$F$71,1)+1,1))+INDEX('Մոդելներ և պարտադիր վճարներ'!$E$67:$E$71,IFERROR(MATCH($W8,'Մոդելներ և պարտադիր վճարներ'!$F$67:$F$71,1)+1,1)))*'Մոդելներ և պարտադիր վճարներ'!$C$59) -> 307733.33 | AC8: =IF(COUNTIFS('Մոդելներ և պարտադիր վճարներ'!$B$35:$B$37,$D8,'Մոդելներ և պարտադիր վճարներ'!$C$35:$C$37,"ԱՁ")>0,"Աստիճաններ չեն կիրառվում — հաշիվ-ապրանքագիր",IF(COUNTIFS('Մոդելներ և պարտադիր վճարներ'!$B$35:$B$37,$D8,'Մոդելներ և պարտադիր վճարներ'!$C$35:$C$37,"D2D")>0,"Աստիճաններ չեն կիրառվում — տես D2D բաժինը","Ֆիքս × (1 + աստիճանի %)")) -> Ֆիքս × (1 + աստիճանի %) | AD8: Վաճառքի ղեկավար
B9: Կոմերցիոն | C9: Վաճառք | D9: Վաճառքի մասնագետ | E9: 1 | F9: 3 | G9: 0 | H9: =$F9-$G9 -> 3 | I9: Կրիտիկական | J9: 120000 | K9: =IF(COUNTIFS('Մոդելներ և պարտադիր վճարներ'!$B$35:$B$37,$D9,'Մոդելներ և պարտադիր վճարներ'!$C$35:$C$37,"ԱՁ")>0,0,$O9*'Մոդելներ և պարտադիր վճարներ'!$C$57) -> 33546.667 | L9: =IF(COUNTIFS('Մոդելներ և պարտադիր վճարներ'!$B$35:$B$37,$D9,'Մոդելներ և պարտադիր վճարներ'!$C$35:$C$37,"ԱՁ")>0,0,$O9*'Մոդելներ և պարտադիր վճարներ'!$C$58) -> 8386.6667 | M9: =IF(COUNTIFS('Մոդելներ և պարտադիր վճարներ'!$B$35:$B$37,$D9,'Մոդելներ և պարտադիր վճարներ'!$C$35:$C$37,"ԱՁ")>0,0,INDEX('Մոդելներ և պարտադիր վճարներ'!$D$67:$D$71,IFERROR(MATCH(IFERROR(INDEX('Մոդելներ և պարտադիր վճարներ'!$D$35:$D$37,MATCH($D9,'Մոդելներ և պարտադիր վճարներ'!$B$35:$B$37,0)),$J9*(1+'Մոդելներ և պարտադիր վճարներ'!$C$60)),'Մոդելներ և պարտադիր վճարներ'!$F$67:$F$71,1)+1,1))) -> 1000 | N9: =IF(COUNTIFS('Մոդելներ և պարտադիր վճարներ'!$B$35:$B$37,$D9,'Մոդելներ և պարտադիր վճարներ'!$C$35:$C$37,"ԱՁ")>0,0,INDEX('Մոդելներ և պարտադիր վճարներ'!$E$67:$E$71,IFERROR(MATCH(IFERROR(INDEX('Մոդելներ և պարտադիր վճարներ'!$D$35:$D$37,MATCH($D9,'Մոդելներ և պարտադիր վճարներ'!$B$35:$B$37,0)),$J9*(1+'Մոդելներ և պարտադիր վճարներ'!$C$60)),'Մոդելներ և պարտադիր վճարներ'!$F$67:$F$71,1)+1,1))) -> 4800 | O9: =IF(COUNTIFS('Մոդելներ և պարտադիր վճարներ'!$B$35:$B$37,$D9,'Մոդելներ և պարտադիր վճարներ'!$C$35:$C$37,"ԱՁ")>0,$J9,($J9+$M9+$N9)*'Մոդելներ և պարտադիր վճարներ'!$C$59) -> 167733.33 | P9: =F9*$J9 -> 360000 | Q9: =O9*F9 -> 503200 | R9: =IF(COUNTIFS('Մոդելներ և պարտադիր վճարներ'!$B$35:$B$37,$D9,'Մոդելներ և պարտադիր վճարներ'!$C$35:$C$37,"ԱՁ")>0,"Գ. ԱՁ",IF(COUNTIFS('Մոդելներ և պարտադիր վճարներ'!$B$35:$B$37,$D9,'Մոդելներ և պարտադիր վճարներ'!$C$35:$C$37,"D2D")>0,"Բ. D2D","Ա. Ֆիքս + KPI բոնուս")) -> Ա. Ֆիքս + KPI բոնուս | S9: =IF(COUNTIFS('Մոդելներ և պարտադիր վճարներ'!$B$35:$B$37,$D9,'Մոդելներ և պարտադիր վճարներ'!$C$35:$C$37,"ԱՁ")>0,$J9,IF(COUNTIFS('Մոդելներ և պարտադիր վճարներ'!$B$35:$B$37,$D9,'Մոդելներ և պարտադիր վճարներ'!$C$35:$C$37,"D2D")>0,'Մոդելներ և պարտադիր վճարներ'!$G$26,$J9*(1+'Մոդելներ և պարտադիր վճարներ'!$D$7))) -> 120000 | T9: =IF(COUNTIFS('Մոդելներ և պարտադիր վճարներ'!$B$35:$B$37,$D9,'Մոդելներ և պարտադիր վճարներ'!$C$35:$C$37,"ԱՁ")>0,$J9,IF(COUNTIFS('Մոդելներ և պարտադիր վճարներ'!$B$35:$B$37,$D9,'Մոդելներ և պարտադիր վճարներ'!$C$35:$C$37,"D2D")>0,'Մոդելներ և պարտադիր վճարներ'!$G$27,$J9*(1+'Մոդելներ և պարտադիր վճարներ'!$D$8))) -> 138000 | U9: =IF(COUNTIFS('Մոդելներ և պարտադիր վճարներ'!$B$35:$B$37,$D9,'Մոդելներ և պարտադիր վճարներ'!$C$35:$C$37,"ԱՁ")>0,$J9,IF(COUNTIFS('Մոդելներ և պարտադիր վճարներ'!$B$35:$B$37,$D9,'Մոդելներ և պարտադիր վճարներ'!$C$35:$C$37,"D2D")>0,'Մոդելներ և պարտադիր վճարներ'!$G$28,$J9*(1+'Մոդելներ և պարտադիր վճարներ'!$D$9))) -> 150000 | V9: =IF(COUNTIFS('Մոդելներ և պարտադիր վճարներ'!$B$35:$B$37,$D9,'Մոդելներ և պարտադիր վճարներ'!$C$35:$C$37,"ԱՁ")>0,$J9,IF(COUNTIFS('Մոդելներ և պարտադիր վճարներ'!$B$35:$B$37,$D9,'Մոդելներ և պարտադիր վճարներ'!$C$35:$C$37,"D2D")>0,'Մոդելներ և պարտադիր վճարներ'!$G$29,$J9*(1+'Մոդելներ և պարտադիր վճարներ'!$D$10))) -> 162000 | W9: =IF(COUNTIFS('Մոդելներ և պարտադիր վճարներ'!$B$35:$B$37,$D9,'Մոդելներ և պարտադիր վճարներ'!$C$35:$C$37,"ԱՁ")>0,$J9,IF(COUNTIFS('Մոդելներ և պարտադիր վճարներ'!$B$35:$B$37,$D9,'Մոդելներ և պարտադիր վճարներ'!$C$35:$C$37,"D2D")>0,'Մոդելներ և պարտադիր վճարներ'!$G$30,$J9*(1+'Մոդելներ և պարտադիր վճարներ'!$D$11))) -> 180000 | X9: =IF(COUNTIFS('Մոդելներ և պարտադիր վճարներ'!$B$35:$B$37,$D9,'Մոդելներ և պարտադիր վճարներ'!$C$35:$C$37,"ԱՁ")>0,$J9,($S9+INDEX('Մոդելներ և պարտադիր վճարներ'!$D$67:$D$71,IFERROR(MATCH($S9,'Մոդելներ և պարտադիր վճարներ'!$F$67:$F$71,1)+1,1))+INDEX('Մոդելներ և պարտադիր վճարներ'!$E$67:$E$71,IFERROR(MATCH($S9,'Մոդելներ և պարտադիր վճարներ'!$F$67:$F$71,1)+1,1)))*'Մոդելներ և պարտադիր վճարներ'!$C$59) -> 161333.33 | Y9: =IF(COUNTIFS('Մոդելներ և պարտադիր վճարներ'!$B$35:$B$37,$D9,'Մոդելներ և պարտադիր վճարներ'!$C$35:$C$37,"ԱՁ")>0,$J9,($T9+INDEX('Մոդելներ և պարտադիր վճարներ'!$D$67:$D$71,IFERROR(MATCH($T9,'Մոդելներ և պարտադիր վճարներ'!$F$67:$F$71,1)+1,1))+INDEX('Մոդելներ և պարտադիր վճարներ'!$E$67:$E$71,IFERROR(MATCH($T9,'Մոդելներ և պարտադիր վճարներ'!$F$67:$F$71,1)+1,1)))*'Մոդելներ և պարտադիր վճարներ'!$C$59) -> 185333.33 | Z9: =IF(COUNTIFS('Մոդելներ և պարտադիր վճարներ'!$B$35:$B$37,$D9,'Մոդելներ և պարտադիր վճարներ'!$C$35:$C$37,"ԱՁ")>0,$J9,($U9+INDEX('Մոդելներ և պարտադիր վճարներ'!$D$67:$D$71,IFERROR(MATCH($U9,'Մոդելներ և պարտադիր վճարներ'!$F$67:$F$71,1)+1,1))+INDEX('Մոդելներ և պարտադիր վճարներ'!$E$67:$E$71,IFERROR(MATCH($U9,'Մոդելներ և պարտադիր վճարներ'!$F$67:$F$71,1)+1,1)))*'Մոդելներ և պարտադիր վճարներ'!$C$59) -> 207733.33 | AA9: =IF(COUNTIFS('Մոդելներ և պարտադիր վճարներ'!$B$35:$B$37,$D9,'Մոդելներ և պարտադիր վճարներ'!$C$35:$C$37,"ԱՁ")>0,$J9,($V9+INDEX('Մոդելներ և պարտադիր վճարներ'!$D$67:$D$71,IFERROR(MATCH($V9,'Մոդելներ և պարտադիր վճարներ'!$F$67:$F$71,1)+1,1))+INDEX('Մոդելներ և պարտադիր վճարներ'!$E$67:$E$71,IFERROR(MATCH($V9,'Մոդելներ և պարտադիր վճարներ'!$F$67:$F$71,1)+1,1)))*'Մոդելներ և պարտադիր վճարներ'!$C$59) -> 223733.33 | AB9: =IF(COUNTIFS('Մոդելներ և պարտադիր վճարներ'!$B$35:$B$37,$D9,'Մոդելներ և պարտադիր վճարներ'!$C$35:$C$37,"ԱՁ")>0,$J9,($W9+INDEX('Մոդելներ և պարտադիր վճարներ'!$D$67:$D$71,IFERROR(MATCH($W9,'Մոդելներ և պարտադիր վճարներ'!$F$67:$F$71,1)+1,1))+INDEX('Մոդելներ և պարտադիր վճարներ'!$E$67:$E$71,IFERROR(MATCH($W9,'Մոդելներ և պարտադիր վճարներ'!$F$67:$F$71,1)+1,1)))*'Մոդելներ և պարտադիր վճարներ'!$C$59) -> 247733.33 | AC9: =IF(COUNTIFS('Մոդելներ և պարտադիր վճարներ'!$B$35:$B$37,$D9,'Մոդելներ և պարտադիր վճարներ'!$C$35:$C$37,"ԱՁ")>0,"Աստիճաններ չեն կիրառվում — հաշիվ-ապրանքագիր",IF(COUNTIFS('Մոդելներ և պարտադիր վճարներ'!$B$35:$B$37,$D9,'Մոդելներ և պարտադիր վճարներ'!$C$35:$C$37,"D2D")>0,"Աստիճաններ չեն կիրառվում — տես D2D բաժինը","Ֆիքս × (1 + աստիճանի %)")) -> Ֆիքս × (1 + աստիճանի %) | AD9: Վաճառքի և սպասարկման ավագ մասնագետ
B10: Կոմերցիոն | C10: Վաճառք | D10: Հեռախոսային վաճառքի ավագ մասնագետ | E10: 1 | F10: 1 | G10: 1 | H10: =$F10-$G10 -> 0 | I10: Համալրված | J10: 150000 | K10: =IF(COUNTIFS('Մոդելներ և պարտադիր վճարներ'!$B$35:$B$37,$D10,'Մոդելներ և պարտադիր վճարներ'!$C$35:$C$37,"ԱՁ")>0,0,$O10*'Մոդելներ և պարտադիր վճարներ'!$C$57) -> 41546.667 | L10: =IF(COUNTIFS('Մոդելներ և պարտադիր վճարներ'!$B$35:$B$37,$D10,'Մոդելներ և պարտադիր վճարներ'!$C$35:$C$37,"ԱՁ")>0,0,$O10*'Մոդելներ և պարտադիր վճարներ'!$C$58) -> 10386.667 | M10: =IF(COUNTIFS('Մոդելներ և պարտադիր վճարներ'!$B$35:$B$37,$D10,'Մոդելներ և պարտադիր վճարներ'!$C$35:$C$37,"ԱՁ")>0,0,INDEX('Մոդելներ և պարտադիր վճարներ'!$D$67:$D$71,IFERROR(MATCH(IFERROR(INDEX('Մոդելներ և պարտադիր վճարներ'!$D$35:$D$37,MATCH($D10,'Մոդելներ և պարտադիր վճարներ'!$B$35:$B$37,0)),$J10*(1+'Մոդելներ և պարտադիր վճարներ'!$C$60)),'Մոդելներ և պարտադիր վճարներ'!$F$67:$F$71,1)+1,1))) -> 1000 | N10: =IF(COUNTIFS('Մոդելներ և պարտադիր վճարներ'!$B$35:$B$37,$D10,'Մոդելներ և պարտադիր վճարներ'!$C$35:$C$37,"ԱՁ")>0,0,INDEX('Մոդելներ և պարտադիր վճարներ'!$E$67:$E$71,IFERROR(MATCH(IFERROR(INDEX('Մոդելներ և պարտադիր վճարներ'!$D$35:$D$37,MATCH($D10,'Մոդելներ և պարտադիր վճարներ'!$B$35:$B$37,0)),$J10*(1+'Մոդելներ և պարտադիր վճարներ'!$C$60)),'Մոդելներ և պարտադիր վճարներ'!$F$67:$F$71,1)+1,1))) -> 4800 | O10: =IF(COUNTIFS('Մոդելներ և պարտադիր վճարներ'!$B$35:$B$37,$D10,'Մոդելներ և պարտադիր վճարներ'!$C$35:$C$37,"ԱՁ")>0,$J10,($J10+$M10+$N10)*'Մոդելներ և պարտադիր վճարներ'!$C$59) -> 207733.33 | P10: =F10*$J10 -> 150000 | Q10: =O10*F10 -> 207733.33 | R10: =IF(COUNTIFS('Մոդելներ և պարտադիր վճարներ'!$B$35:$B$37,$D10,'Մոդելներ և պարտադիր վճարներ'!$C$35:$C$37,"ԱՁ")>0,"Գ. ԱՁ",IF(COUNTIFS('Մոդելներ և պարտադիր վճարներ'!$B$35:$B$37,$D10,'Մոդելներ և պարտադիր վճարներ'!$C$35:$C$37,"D2D")>0,"Բ. D2D","Ա. Ֆիքս + KPI բոնուս")) -> Ա. Ֆիքս + KPI բոնուս | S10: =IF(COUNTIFS('Մոդելներ և պարտադիր վճարներ'!$B$35:$B$37,$D10,'Մոդելներ և պարտադիր վճարներ'!$C$35:$C$37,"ԱՁ")>0,$J10,IF(COUNTIFS('Մոդելներ և պարտադիր վճարներ'!$B$35:$B$37,$D10,'Մոդելներ և պարտադիր վճարներ'!$C$35:$C$37,"D2D")>0,'Մոդելներ և պարտադիր վճարներ'!$G$26,$J10*(1+'Մոդելներ և պարտադիր վճարներ'!$D$7))) -> 150000 | T10: =IF(COUNTIFS('Մոդելներ և պարտադիր վճարներ'!$B$35:$B$37,$D10,'Մոդելներ և պարտադիր վճարներ'!$C$35:$C$37,"ԱՁ")>0,$J10,IF(COUNTIFS('Մոդելներ և պարտադիր վճարներ'!$B$35:$B$37,$D10,'Մոդելներ և պարտադիր վճարներ'!$C$35:$C$37,"D2D")>0,'Մոդելներ և պարտադիր վճարներ'!$G$27,$J10*(1+'Մոդելներ և պարտադիր վճարներ'!$D$8))) -> 172500 | U10: =IF(COUNTIFS('Մոդելներ և պարտադիր վճարներ'!$B$35:$B$37,$D10,'Մոդելներ և պարտադիր վճարներ'!$C$35:$C$37,"ԱՁ")>0,$J10,IF(COUNTIFS('Մոդելներ և պարտադիր վճարներ'!$B$35:$B$37,$D10,'Մոդելներ և պարտադիր վճարներ'!$C$35:$C$37,"D2D")>0,'Մոդելներ և պարտադիր վճարներ'!$G$28,$J10*(1+'Մոդելներ և պարտադիր վճարներ'!$D$9))) -> 187500 | V10: =IF(COUNTIFS('Մոդելներ և պարտադիր վճարներ'!$B$35:$B$37,$D10,'Մոդելներ և պարտադիր վճարներ'!$C$35:$C$37,"ԱՁ")>0,$J10,IF(COUNTIFS('Մոդելներ և պարտադիր վճարներ'!$B$35:$B$37,$D10,'Մոդելներ և պարտադիր վճարներ'!$C$35:$C$37,"D2D")>0,'Մոդելներ և պարտադիր վճարներ'!$G$29,$J10*(1+'Մոդելներ և պարտադիր վճարներ'!$D$10))) -> 202500 | W10: =IF(COUNTIFS('Մոդելներ և պարտադիր վճարներ'!$B$35:$B$37,$D10,'Մոդելներ և պարտադիր վճարներ'!$C$35:$C$37,"ԱՁ")>0,$J10,IF(COUNTIFS('Մոդելներ և պարտադիր վճարներ'!$B$35:$B$37,$D10,'Մոդելներ և պարտադիր վճարներ'!$C$35:$C$37,"D2D")>0,'Մոդելներ և պարտադիր վճարներ'!$G$30,$J10*(1+'Մոդելներ և պարտադիր վճարներ'!$D$11))) -> 225000 | X10: =IF(COUNTIFS('Մոդելներ և պարտադիր վճարներ'!$B$35:$B$37,$D10,'Մոդելներ և պարտադիր վճարներ'!$C$35:$C$37,"ԱՁ")>0,$J10,($S10+INDEX('Մոդելներ և պարտադիր վճարներ'!$D$67:$D$71,IFERROR(MATCH($S10,'Մոդելներ և պարտադիր վճարներ'!$F$67:$F$71,1)+1,1))+INDEX('Մոդելներ և պարտադիր վճարներ'!$E$67:$E$71,IFERROR(MATCH($S10,'Մոդելներ և պարտադիր վճարներ'!$F$67:$F$71,1)+1,1)))*'Մոդելներ և պարտադիր վճարներ'!$C$59) -> 207733.33 | Y10: =IF(COUNTIFS('Մոդելներ և պարտադիր վճարներ'!$B$35:$B$37,$D10,'Մոդելներ և պարտադիր վճարներ'!$C$35:$C$37,"ԱՁ")>0,$J10,($T10+INDEX('Մոդելներ և պարտադիր վճարներ'!$D$67:$D$71,IFERROR(MATCH($T10,'Մոդելներ և պարտադիր վճարներ'!$F$67:$F$71,1)+1,1))+INDEX('Մոդելներ և պարտադիր վճարներ'!$E$67:$E$71,IFERROR(MATCH($T10,'Մոդելներ և պարտադիր վճարներ'!$F$67:$F$71,1)+1,1)))*'Մոդելներ և պարտադիր վճարներ'!$C$59) -> 237733.33 | Z10: =IF(COUNTIFS('Մոդելներ և պարտադիր վճարներ'!$B$35:$B$37,$D10,'Մոդելներ և պարտադիր վճարներ'!$C$35:$C$37,"ԱՁ")>0,$J10,($U10+INDEX('Մոդելներ և պարտադիր վճարներ'!$D$67:$D$71,IFERROR(MATCH($U10,'Մոդելներ և պարտադիր վճարներ'!$F$67:$F$71,1)+1,1))+INDEX('Մոդելներ և պարտադիր վճարներ'!$E$67:$E$71,IFERROR(MATCH($U10,'Մոդելներ և պարտադիր վճարներ'!$F$67:$F$71,1)+1,1)))*'Մոդելներ և պարտադիր վճարներ'!$C$59) -> 257733.33 | AA10: =IF(COUNTIFS('Մոդելներ և պարտադիր վճարներ'!$B$35:$B$37,$D10,'Մոդելներ և պարտադիր վճարներ'!$C$35:$C$37,"ԱՁ")>0,$J10,($V10+INDEX('Մոդելներ և պարտադիր վճարներ'!$D$67:$D$71,IFERROR(MATCH($V10,'Մոդելներ և պարտադիր վճարներ'!$F$67:$F$71,1)+1,1))+INDEX('Մոդելներ և պարտադիր վճարներ'!$E$67:$E$71,IFERROR(MATCH($V10,'Մոդելներ և պարտադիր վճարներ'!$F$67:$F$71,1)+1,1)))*'Մոդելներ և պարտադիր վճարներ'!$C$59) -> 277733.33 | AB10: =IF(COUNTIFS('Մոդելներ և պարտադիր վճարներ'!$B$35:$B$37,$D10,'Մոդելներ և պարտադիր վճարներ'!$C$35:$C$37,"ԱՁ")>0,$J10,($W10+INDEX('Մոդելներ և պարտադիր վճարներ'!$D$67:$D$71,IFERROR(MATCH($W10,'Մոդելներ և պարտադիր վճարներ'!$F$67:$F$71,1)+1,1))+INDEX('Մոդելներ և պարտադիր վճարներ'!$E$67:$E$71,IFERROR(MATCH($W10,'Մոդելներ և պարտադիր վճարներ'!$F$67:$F$71,1)+1,1)))*'Մոդելներ և պարտադիր վճարներ'!$C$59) -> 307733.33 | AC10: =IF(COUNTIFS('Մոդելներ և պարտադիր վճարներ'!$B$35:$B$37,$D10,'Մոդելներ և պարտադիր վճարներ'!$C$35:$C$37,"ԱՁ")>0,"Աստիճաններ չեն կիրառվում — հաշիվ-ապրանքագիր",IF(COUNTIFS('Մոդելներ և պարտադիր վճարներ'!$B$35:$B$37,$D10,'Մոդելներ և պարտադիր վճարներ'!$C$35:$C$37,"D2D")>0,"Աստիճաններ չեն կիրառվում — տես D2D բաժինը","Ֆիքս × (1 + աստիճանի %)")) -> Ֆիքս × (1 + աստիճանի %) | AD10: Վաճառքի ղեկավար
B11: Կոմերցիոն | C11: Վաճառք | D11: Հեռախոսային վաճառքի գործակալ | E11: 1 | F11: 2 | G11: 0 | H11: =$F11-$G11 -> 2 | I11: Կրիտիկական | J11: 100000 | K11: =IF(COUNTIFS('Մոդելներ և պարտադիր վճարներ'!$B$35:$B$37,$D11,'Մոդելներ և պարտադիր վճարներ'!$C$35:$C$37,"ԱՁ")>0,0,$O11*'Մոդելներ և պարտադիր վճարներ'!$C$57) -> 28213.333 | L11: =IF(COUNTIFS('Մոդելներ և պարտադիր վճարներ'!$B$35:$B$37,$D11,'Մոդելներ և պարտադիր վճարներ'!$C$35:$C$37,"ԱՁ")>0,0,$O11*'Մոդելներ և պարտադիր վճարներ'!$C$58) -> 7053.3333 | M11: =IF(COUNTIFS('Մոդելներ և պարտադիր վճարներ'!$B$35:$B$37,$D11,'Մոդելներ և պարտադիր վճարներ'!$C$35:$C$37,"ԱՁ")>0,0,INDEX('Մոդելներ և պարտադիր վճարներ'!$D$67:$D$71,IFERROR(MATCH(IFERROR(INDEX('Մոդելներ և պարտադիր վճարներ'!$D$35:$D$37,MATCH($D11,'Մոդելներ և պարտադիր վճարներ'!$B$35:$B$37,0)),$J11*(1+'Մոդելներ և պարտադիր վճարներ'!$C$60)),'Մոդելներ և պարտադիր վճարներ'!$F$67:$F$71,1)+1,1))) -> 1000 | N11: =IF(COUNTIFS('Մոդելներ և պարտադիր վճարներ'!$B$35:$B$37,$D11,'Մոդելներ և պարտադիր վճարներ'!$C$35:$C$37,"ԱՁ")>0,0,INDEX('Մոդելներ և պարտադիր վճարներ'!$E$67:$E$71,IFERROR(MATCH(IFERROR(INDEX('Մոդելներ և պարտադիր վճարներ'!$D$35:$D$37,MATCH($D11,'Մոդելներ և պարտադիր վճարներ'!$B$35:$B$37,0)),$J11*(1+'Մոդելներ և պարտադիր վճարներ'!$C$60)),'Մոդելներ և պարտադիր վճարներ'!$F$67:$F$71,1)+1,1))) -> 4800 | O11: =IF(COUNTIFS('Մոդելներ և պարտադիր վճարներ'!$B$35:$B$37,$D11,'Մոդելներ և պարտադիր վճարներ'!$C$35:$C$37,"ԱՁ")>0,$J11,($J11+$M11+$N11)*'Մոդելներ և պարտադիր վճարներ'!$C$59) -> 141066.67 | P11: =F11*$J11 -> 200000 | Q11: =O11*F11 -> 282133.33 | R11: =IF(COUNTIFS('Մոդելներ և պարտադիր վճարներ'!$B$35:$B$37,$D11,'Մոդելներ և պարտադիր վճարներ'!$C$35:$C$37,"ԱՁ")>0,"Գ. ԱՁ",IF(COUNTIFS('Մոդելներ և պարտադիր վճարներ'!$B$35:$B$37,$D11,'Մոդելներ և պարտադիր վճարներ'!$C$35:$C$37,"D2D")>0,"Բ. D2D","Ա. Ֆիքս + KPI բոնուս")) -> Ա. Ֆիքս + KPI բոնուս | S11: =IF(COUNTIFS('Մոդելներ և պարտադիր վճարներ'!$B$35:$B$37,$D11,'Մոդելներ և պարտադիր վճարներ'!$C$35:$C$37,"ԱՁ")>0,$J11,IF(COUNTIFS('Մոդելներ և պարտադիր վճարներ'!$B$35:$B$37,$D11,'Մոդելներ և պարտադիր վճարներ'!$C$35:$C$37,"D2D")>0,'Մոդելներ և պարտադիր վճարներ'!$G$26,$J11*(1+'Մոդելներ և պարտադիր վճարներ'!$D$7))) -> 100000 | T11: =IF(COUNTIFS('Մոդելներ և պարտադիր վճարներ'!$B$35:$B$37,$D11,'Մոդելներ և պարտադիր վճարներ'!$C$35:$C$37,"ԱՁ")>0,$J11,IF(COUNTIFS('Մոդելներ և պարտադիր վճարներ'!$B$35:$B$37,$D11,'Մոդելներ և պարտադիր վճարներ'!$C$35:$C$37,"D2D")>0,'Մոդելներ և պարտադիր վճարներ'!$G$27,$J11*(1+'Մոդելներ և պարտադիր վճարներ'!$D$8))) -> 115000 | U11: =IF(COUNTIFS('Մոդելներ և պարտադիր վճարներ'!$B$35:$B$37,$D11,'Մոդելներ և պարտադիր վճարներ'!$C$35:$C$37,"ԱՁ")>0,$J11,IF(COUNTIFS('Մոդելներ և պարտադիր վճարներ'!$B$35:$B$37,$D11,'Մոդելներ և պարտադիր վճարներ'!$C$35:$C$37,"D2D")>0,'Մոդելներ և պարտադիր վճարներ'!$G$28,$J11*(1+'Մոդելներ և պարտադիր վճարներ'!$D$9))) -> 125000 | V11: =IF(COUNTIFS('Մոդելներ և պարտադիր վճարներ'!$B$35:$B$37,$D11,'Մոդելներ և պարտադիր վճարներ'!$C$35:$C$37,"ԱՁ")>0,$J11,IF(COUNTIFS('Մոդելներ և պարտադիր վճարներ'!$B$35:$B$37,$D11,'Մոդելներ և պարտադիր վճարներ'!$C$35:$C$37,"D2D")>0,'Մոդելներ և պարտադիր վճարներ'!$G$29,$J11*(1+'Մոդելներ և պարտադիր վճարներ'!$D$10))) -> 135000 | W11: =IF(COUNTIFS('Մոդելներ և պարտադիր վճարներ'!$B$35:$B$37,$D11,'Մոդելներ և պարտադիր վճարներ'!$C$35:$C$37,"ԱՁ")>0,$J11,IF(COUNTIFS('Մոդելներ և պարտադիր վճարներ'!$B$35:$B$37,$D11,'Մոդելներ և պարտադիր վճարներ'!$C$35:$C$37,"D2D")>0,'Մոդելներ և պարտադիր վճարներ'!$G$30,$J11*(1+'Մոդելներ և պարտադիր վճարներ'!$D$11))) -> 150000 | X11: =IF(COUNTIFS('Մոդելներ և պարտադիր վճարներ'!$B$35:$B$37,$D11,'Մոդելներ և պարտադիր վճարներ'!$C$35:$C$37,"ԱՁ")>0,$J11,($S11+INDEX('Մոդելներ և պարտադիր վճարներ'!$D$67:$D$71,IFERROR(MATCH($S11,'Մոդելներ և պարտադիր վճարներ'!$F$67:$F$71,1)+1,1))+INDEX('Մոդելներ և պարտադիր վճարներ'!$E$67:$E$71,IFERROR(MATCH($S11,'Մոդելներ և պարտադիր վճարներ'!$F$67:$F$71,1)+1,1)))*'Մոդելներ և պարտադիր վճարներ'!$C$59) -> 134666.67 | Y11: =IF(COUNTIFS('Մոդելներ և պարտադիր վճարներ'!$B$35:$B$37,$D11,'Մոդելներ և պարտադիր վճարներ'!$C$35:$C$37,"ԱՁ")>0,$J11,($T11+INDEX('Մոդելներ և պարտադիր վճարներ'!$D$67:$D$71,IFERROR(MATCH($T11,'Մոդելներ և պարտադիր վճարներ'!$F$67:$F$71,1)+1,1))+INDEX('Մոդելներ և պարտադիր վճարներ'!$E$67:$E$71,IFERROR(MATCH($T11,'Մոդելներ և պարտադիր վճարներ'!$F$67:$F$71,1)+1,1)))*'Մոդելներ և պարտադիր վճարներ'!$C$59) -> 154666.67 | Z11: =IF(COUNTIFS('Մոդելներ և պարտադիր վճարներ'!$B$35:$B$37,$D11,'Մոդելներ և պարտադիր վճարներ'!$C$35:$C$37,"ԱՁ")>0,$J11,($U11+INDEX('Մոդելներ և պարտադիր վճարներ'!$D$67:$D$71,IFERROR(MATCH($U11,'Մոդելներ և պարտադիր վճարներ'!$F$67:$F$71,1)+1,1))+INDEX('Մոդելներ և պարտադիր վճարներ'!$E$67:$E$71,IFERROR(MATCH($U11,'Մոդելներ և պարտադիր վճարներ'!$F$67:$F$71,1)+1,1)))*'Մոդելներ և պարտադիր վճարներ'!$C$59) -> 168000 | AA11: =IF(COUNTIFS('Մոդելներ և պարտադիր վճարներ'!$B$35:$B$37,$D11,'Մոդելներ և պարտադիր վճարներ'!$C$35:$C$37,"ԱՁ")>0,$J11,($V11+INDEX('Մոդելներ և պարտադիր վճարներ'!$D$67:$D$71,IFERROR(MATCH($V11,'Մոդելներ և պարտադիր վճարներ'!$F$67:$F$71,1)+1,1))+INDEX('Մոդելներ և պարտադիր վճարներ'!$E$67:$E$71,IFERROR(MATCH($V11,'Մոդելներ և պարտադիր վճարներ'!$F$67:$F$71,1)+1,1)))*'Մոդելներ և պարտադիր վճարներ'!$C$59) -> 181333.33 | AB11: =IF(COUNTIFS('Մոդելներ և պարտադիր վճարներ'!$B$35:$B$37,$D11,'Մոդելներ և պարտադիր վճարներ'!$C$35:$C$37,"ԱՁ")>0,$J11,($W11+INDEX('Մոդելներ և պարտադիր վճարներ'!$D$67:$D$71,IFERROR(MATCH($W11,'Մոդելներ և պարտադիր վճարներ'!$F$67:$F$71,1)+1,1))+INDEX('Մոդելներ և պարտադիր վճարներ'!$E$67:$E$71,IFERROR(MATCH($W11,'Մոդելներ և պարտադիր վճարներ'!$F$67:$F$71,1)+1,1)))*'Մոդելներ և պարտադիր վճարներ'!$C$59) -> 207733.33 | AC11: =IF(COUNTIFS('Մոդելներ և պարտադիր վճարներ'!$B$35:$B$37,$D11,'Մոդելներ և պարտադիր վճարներ'!$C$35:$C$37,"ԱՁ")>0,"Աստիճաններ չեն կիրառվում — հաշիվ-ապրանքագիր",IF(COUNTIFS('Մոդելներ և պարտադիր վճարներ'!$B$35:$B$37,$D11,'Մոդելներ և պարտադիր վճարներ'!$C$35:$C$37,"D2D")>0,"Աստիճաններ չեն կիրառվում — տես D2D բաժինը","Ֆիքս × (1 + աստիճանի %)")) -> Ֆիքս × (1 + աստիճանի %) | AD11: Հեռախոսային վաճառքի ավագ մասնագետ
B12: Կոմերցիոն | C12: Մարքեթինգ | D12: Մարքեթինգի ղեկավար | E12: 1 | F12: 1 | G12: 1 | H12: =$F12-$G12 -> 0 | I12: Համալրված | J12: 150000 | K12: =IF(COUNTIFS('Մոդելներ և պարտադիր վճարներ'!$B$35:$B$37,$D12,'Մոդելներ և պարտադիր վճարներ'!$C$35:$C$37,"ԱՁ")>0,0,$O12*'Մոդելներ և պարտադիր վճարներ'!$C$57) -> 41546.667 | L12: =IF(COUNTIFS('Մոդելներ և պարտադիր վճարներ'!$B$35:$B$37,$D12,'Մոդելներ և պարտադիր վճարներ'!$C$35:$C$37,"ԱՁ")>0,0,$O12*'Մոդելներ և պարտադիր վճարներ'!$C$58) -> 10386.667 | M12: =IF(COUNTIFS('Մոդելներ և պարտադիր վճարներ'!$B$35:$B$37,$D12,'Մոդելներ և պարտադիր վճարներ'!$C$35:$C$37,"ԱՁ")>0,0,INDEX('Մոդելներ և պարտադիր վճարներ'!$D$67:$D$71,IFERROR(MATCH(IFERROR(INDEX('Մոդելներ և պարտադիր վճարներ'!$D$35:$D$37,MATCH($D12,'Մոդելներ և պարտադիր վճարներ'!$B$35:$B$37,0)),$J12*(1+'Մոդելներ և պարտադիր վճարներ'!$C$60)),'Մոդելներ և պարտադիր վճարներ'!$F$67:$F$71,1)+1,1))) -> 1000 | N12: =IF(COUNTIFS('Մոդելներ և պարտադիր վճարներ'!$B$35:$B$37,$D12,'Մոդելներ և պարտադիր վճարներ'!$C$35:$C$37,"ԱՁ")>0,0,INDEX('Մոդելներ և պարտադիր վճարներ'!$E$67:$E$71,IFERROR(MATCH(IFERROR(INDEX('Մոդելներ և պարտադիր վճարներ'!$D$35:$D$37,MATCH($D12,'Մոդելներ և պարտադիր վճարներ'!$B$35:$B$37,0)),$J12*(1+'Մոդելներ և պարտադիր վճարներ'!$C$60)),'Մոդելներ և պարտադիր վճարներ'!$F$67:$F$71,1)+1,1))) -> 4800 | O12: =IF(COUNTIFS('Մոդելներ և պարտադիր վճարներ'!$B$35:$B$37,$D12,'Մոդելներ և պարտադիր վճարներ'!$C$35:$C$37,"ԱՁ")>0,$J12,($J12+$M12+$N12)*'Մոդելներ և պարտադիր վճարներ'!$C$59) -> 207733.33 | P12: =F12*$J12 -> 150000 | Q12: =O12*F12 -> 207733.33 | R12: =IF(COUNTIFS('Մոդելներ և պարտադիր վճարներ'!$B$35:$B$37,$D12,'Մոդելներ և պարտադիր վճարներ'!$C$35:$C$37,"ԱՁ")>0,"Գ. ԱՁ",IF(COUNTIFS('Մոդելներ և պարտադիր վճարներ'!$B$35:$B$37,$D12,'Մոդելներ և պարտադիր վճարներ'!$C$35:$C$37,"D2D")>0,"Բ. D2D","Ա. Ֆիքս + KPI բոնուս")) -> Ա. Ֆիքս + KPI բոնուս | S12: =IF(COUNTIFS('Մոդելներ և պարտադիր վճարներ'!$B$35:$B$37,$D12,'Մոդելներ և պարտադիր վճարներ'!$C$35:$C$37,"ԱՁ")>0,$J12,IF(COUNTIFS('Մոդելներ և պարտադիր վճարներ'!$B$35:$B$37,$D12,'Մոդելներ և պարտադիր վճարներ'!$C$35:$C$37,"D2D")>0,'Մոդելներ և պարտադիր վճարներ'!$G$26,$J12*(1+'Մոդելներ և պարտադիր վճարներ'!$D$7))) -> 150000 | T12: =IF(COUNTIFS('Մոդելներ և պարտադիր վճարներ'!$B$35:$B$37,$D12,'Մոդելներ և պարտադիր վճարներ'!$C$35:$C$37,"ԱՁ")>0,$J12,IF(COUNTIFS('Մոդելներ և պարտադիր վճարներ'!$B$35:$B$37,$D12,'Մոդելներ և պարտադիր վճարներ'!$C$35:$C$37,"D2D")>0,'Մոդելներ և պարտադիր վճարներ'!$G$27,$J12*(1+'Մոդելներ և պարտադիր վճարներ'!$D$8))) -> 172500 | U12: =IF(COUNTIFS('Մոդելներ և պարտադիր վճարներ'!$B$35:$B$37,$D12,'Մոդելներ և պարտադիր վճարներ'!$C$35:$C$37,"ԱՁ")>0,$J12,IF(COUNTIFS('Մոդելներ և պարտադիր վճարներ'!$B$35:$B$37,$D12,'Մոդելներ և պարտադիր վճարներ'!$C$35:$C$37,"D2D")>0,'Մոդելներ և պարտադիր վճարներ'!$G$28,$J12*(1+'Մոդելներ և պարտադիր վճարներ'!$D$9))) -> 187500 | V12: =IF(COUNTIFS('Մոդելներ և պարտադիր վճարներ'!$B$35:$B$37,$D12,'Մոդելներ և պարտադիր վճարներ'!$C$35:$C$37,"ԱՁ")>0,$J12,IF(COUNTIFS('Մոդելներ և պարտադիր վճարներ'!$B$35:$B$37,$D12,'Մոդելներ և պարտադիր վճարներ'!$C$35:$C$37,"D2D")>0,'Մոդելներ և պարտադիր վճարներ'!$G$29,$J12*(1+'Մոդելներ և պարտադիր վճարներ'!$D$10))) -> 202500 | W12: =IF(COUNTIFS('Մոդելներ և պարտադիր վճարներ'!$B$35:$B$37,$D12,'Մոդելներ և պարտադիր վճարներ'!$C$35:$C$37,"ԱՁ")>0,$J12,IF(COUNTIFS('Մոդելներ և պարտադիր վճարներ'!$B$35:$B$37,$D12,'Մոդելներ և պարտադիր վճարներ'!$C$35:$C$37,"D2D")>0,'Մոդելներ և պարտադիր վճարներ'!$G$30,$J12*(1+'Մոդելներ և պարտադիր վճարներ'!$D$11))) -> 225000 | X12: =IF(COUNTIFS('Մոդելներ և պարտադիր վճարներ'!$B$35:$B$37,$D12,'Մոդելներ և պարտադիր վճարներ'!$C$35:$C$37,"ԱՁ")>0,$J12,($S12+INDEX('Մոդելներ և պարտադիր վճարներ'!$D$67:$D$71,IFERROR(MATCH($S12,'Մոդելներ և պարտադիր վճարներ'!$F$67:$F$71,1)+1,1))+INDEX('Մոդելներ և պարտադիր վճարներ'!$E$67:$E$71,IFERROR(MATCH($S12,'Մոդելներ և պարտադիր վճարներ'!$F$67:$F$71,1)+1,1)))*'Մոդելներ և պարտադիր վճարներ'!$C$59) -> 207733.33 | Y12: =IF(COUNTIFS('Մոդելներ և պարտադիր վճարներ'!$B$35:$B$37,$D12,'Մոդելներ և պարտադիր վճարներ'!$C$35:$C$37,"ԱՁ")>0,$J12,($T12+INDEX('Մոդելներ և պարտադիր վճարներ'!$D$67:$D$71,IFERROR(MATCH($T12,'Մոդելներ և պարտադիր վճարներ'!$F$67:$F$71,1)+1,1))+INDEX('Մոդելներ և պարտադիր վճարներ'!$E$67:$E$71,IFERROR(MATCH($T12,'Մոդելներ և պարտադիր վճարներ'!$F$67:$F$71,1)+1,1)))*'Մոդելներ և պարտադիր վճարներ'!$C$59) -> 237733.33 | Z12: =IF(COUNTIFS('Մոդելներ և պարտադիր վճարներ'!$B$35:$B$37,$D12,'Մոդելներ և պարտադիր վճարներ'!$C$35:$C$37,"ԱՁ")>0,$J12,($U12+INDEX('Մոդելներ և պարտադիր վճարներ'!$D$67:$D$71,IFERROR(MATCH($U12,'Մոդելներ և պարտադիր վճարներ'!$F$67:$F$71,1)+1,1))+INDEX('Մոդելներ և պարտադիր վճարներ'!$E$67:$E$71,IFERROR(MATCH($U12,'Մոդելներ և պարտադիր վճարներ'!$F$67:$F$71,1)+1,1)))*'Մոդելներ և պարտադիր վճարներ'!$C$59) -> 257733.33 | AA12: =IF(COUNTIFS('Մոդելներ և պարտադիր վճարներ'!$B$35:$B$37,$D12,'Մոդելներ և պարտադիր վճարներ'!$C$35:$C$37,"ԱՁ")>0,$J12,($V12+INDEX('Մոդելներ և պարտադիր վճարներ'!$D$67:$D$71,IFERROR(MATCH($V12,'Մոդելներ և պարտադիր վճարներ'!$F$67:$F$71,1)+1,1))+INDEX('Մոդելներ և պարտադիր վճարներ'!$E$67:$E$71,IFERROR(MATCH($V12,'Մոդելներ և պարտադիր վճարներ'!$F$67:$F$71,1)+1,1)))*'Մոդելներ և պարտադիր վճարներ'!$C$59) -> 277733.33 | AB12: =IF(COUNTIFS('Մոդելներ և պարտադիր վճարներ'!$B$35:$B$37,$D12,'Մոդելներ և պարտադիր վճարներ'!$C$35:$C$37,"ԱՁ")>0,$J12,($W12+INDEX('Մոդելներ և պարտադիր վճարներ'!$D$67:$D$71,IFERROR(MATCH($W12,'Մոդելներ և պարտադիր վճարներ'!$F$67:$F$71,1)+1,1))+INDEX('Մոդելներ և պարտադիր վճարներ'!$E$67:$E$71,IFERROR(MATCH($W12,'Մոդելներ և պարտադիր վճարներ'!$F$67:$F$71,1)+1,1)))*'Մոդելներ և պարտադիր վճարներ'!$C$59) -> 307733.33 | AC12: =IF(COUNTIFS('Մոդելներ և պարտադիր վճարներ'!$B$35:$B$37,$D12,'Մոդելներ և պարտադիր վճարներ'!$C$35:$C$37,"ԱՁ")>0,"Աստիճաններ չեն կիրառվում — հաշիվ-ապրանքագիր",IF(COUNTIFS('Մոդելներ և պարտադիր վճարներ'!$B$35:$B$37,$D12,'Մոդելներ և պարտադիր վճարներ'!$C$35:$C$37,"D2D")>0,"Աստիճաններ չեն կիրառվում — տես D2D բաժինը","Ֆիքս × (1 + աստիճանի %)")) -> Ֆիքս × (1 + աստիճանի %) | AD12: Վաճառքի և գործառնական ղեկավար
B13: Կոմերցիոն | C13: Մարքեթինգ | D13: Performance Marketing մասնագետ | E13: 1 | F13: 1 | G13: 0 | H13: =$F13-$G13 -> 1 | I13: Կարող է սպասել | J13: 150000 | K13: =IF(COUNTIFS('Մոդելներ և պարտադիր վճարներ'!$B$35:$B$37,$D13,'Մոդելներ և պարտադիր վճարներ'!$C$35:$C$37,"ԱՁ")>0,0,$O13*'Մոդելներ և պարտադիր վճարներ'!$C$57) -> 41546.667 | L13: =IF(COUNTIFS('Մոդելներ և պարտադիր վճարներ'!$B$35:$B$37,$D13,'Մոդելներ և պարտադիր վճարներ'!$C$35:$C$37,"ԱՁ")>0,0,$O13*'Մոդելներ և պարտադիր վճարներ'!$C$58) -> 10386.667 | M13: =IF(COUNTIFS('Մոդելներ և պարտադիր վճարներ'!$B$35:$B$37,$D13,'Մոդելներ և պարտադիր վճարներ'!$C$35:$C$37,"ԱՁ")>0,0,INDEX('Մոդելներ և պարտադիր վճարներ'!$D$67:$D$71,IFERROR(MATCH(IFERROR(INDEX('Մոդելներ և պարտադիր վճարներ'!$D$35:$D$37,MATCH($D13,'Մոդելներ և պարտադիր վճարներ'!$B$35:$B$37,0)),$J13*(1+'Մոդելներ և պարտադիր վճարներ'!$C$60)),'Մոդելներ և պարտադիր վճարներ'!$F$67:$F$71,1)+1,1))) -> 1000 | N13: =IF(COUNTIFS('Մոդելներ և պարտադիր վճարներ'!$B$35:$B$37,$D13,'Մոդելներ և պարտադիր վճարներ'!$C$35:$C$37,"ԱՁ")>0,0,INDEX('Մոդելներ և պարտադիր վճարներ'!$E$67:$E$71,IFERROR(MATCH(IFERROR(INDEX('Մոդելներ և պարտադիր վճարներ'!$D$35:$D$37,MATCH($D13,'Մոդելներ և պարտադիր վճարներ'!$B$35:$B$37,0)),$J13*(1+'Մոդելներ և պարտադիր վճարներ'!$C$60)),'Մոդելներ և պարտադիր վճարներ'!$F$67:$F$71,1)+1,1))) -> 4800 | O13: =IF(COUNTIFS('Մոդելներ և պարտադիր վճարներ'!$B$35:$B$37,$D13,'Մոդելներ և պարտադիր վճարներ'!$C$35:$C$37,"ԱՁ")>0,$J13,($J13+$M13+$N13)*'Մոդելներ և պարտադիր վճարներ'!$C$59) -> 207733.33 | P13: =F13*$J13 -> 150000 | Q13: =O13*F13 -> 207733.33 | R13: =IF(COUNTIFS('Մոդելներ և պարտադիր վճարներ'!$B$35:$B$37,$D13,'Մոդելներ և պարտադիր վճարներ'!$C$35:$C$37,"ԱՁ")>0,"Գ. ԱՁ",IF(COUNTIFS('Մոդելներ և պարտադիր վճարներ'!$B$35:$B$37,$D13,'Մոդելներ և պարտադիր վճարներ'!$C$35:$C$37,"D2D")>0,"Բ. D2D","Ա. Ֆիքս + KPI բոնուս")) -> Ա. Ֆիքս + KPI բոնուս | S13: =IF(COUNTIFS('Մոդելներ և պարտադիր վճարներ'!$B$35:$B$37,$D13,'Մոդելներ և պարտադիր վճարներ'!$C$35:$C$37,"ԱՁ")>0,$J13,IF(COUNTIFS('Մոդելներ և պարտադիր վճարներ'!$B$35:$B$37,$D13,'Մոդելներ և պարտադիր վճարներ'!$C$35:$C$37,"D2D")>0,'Մոդելներ և պարտադիր վճարներ'!$G$26,$J13*(1+'Մոդելներ և պարտադիր վճարներ'!$D$7))) -> 150000 | T13: =IF(COUNTIFS('Մոդելներ և պարտադիր վճարներ'!$B$35:$B$37,$D13,'Մոդելներ և պարտադիր վճարներ'!$C$35:$C$37,"ԱՁ")>0,$J13,IF(COUNTIFS('Մոդելներ և պարտադիր վճարներ'!$B$35:$B$37,$D13,'Մոդելներ և պարտադիր վճարներ'!$C$35:$C$37,"D2D")>0,'Մոդելներ և պարտադիր վճարներ'!$G$27,$J13*(1+'Մոդելներ և պարտադիր վճարներ'!$D$8))) -> 172500 | U13: =IF(COUNTIFS('Մոդելներ և պարտադիր վճարներ'!$B$35:$B$37,$D13,'Մոդելներ և պարտադիր վճարներ'!$C$35:$C$37,"ԱՁ")>0,$J13,IF(COUNTIFS('Մոդելներ և պարտադիր վճարներ'!$B$35:$B$37,$D13,'Մոդելներ և պարտադիր վճարներ'!$C$35:$C$37,"D2D")>0,'Մոդելներ և պարտադիր վճարներ'!$G$28,$J13*(1+'Մոդելներ և պարտադիր վճարներ'!$D$9))) -> 187500 | V13: =IF(COUNTIFS('Մոդելներ և պարտադիր վճարներ'!$B$35:$B$37,$D13,'Մոդելներ և պարտադիր վճարներ'!$C$35:$C$37,"ԱՁ")>0,$J13,IF(COUNTIFS('Մոդելներ և պարտադիր վճարներ'!$B$35:$B$37,$D13,'Մոդելներ և պարտադիր վճարներ'!$C$35:$C$37,"D2D")>0,'Մոդելներ և պարտադիր վճարներ'!$G$29,$J13*(1+'Մոդելներ և պարտադիր վճարներ'!$D$10))) -> 202500 | W13: =IF(COUNTIFS('Մոդելներ և պարտադիր վճարներ'!$B$35:$B$37,$D13,'Մոդելներ և պարտադիր վճարներ'!$C$35:$C$37,"ԱՁ")>0,$J13,IF(COUNTIFS('Մոդելներ և պարտադիր վճարներ'!$B$35:$B$37,$D13,'Մոդելներ և պարտադիր վճարներ'!$C$35:$C$37,"D2D")>0,'Մոդելներ և պարտադիր վճարներ'!$G$30,$J13*(1+'Մոդելներ և պարտադիր վճարներ'!$D$11))) -> 225000 | X13: =IF(COUNTIFS('Մոդելներ և պարտադիր վճարներ'!$B$35:$B$37,$D13,'Մոդելներ և պարտադիր վճարներ'!$C$35:$C$37,"ԱՁ")>0,$J13,($S13+INDEX('Մոդելներ և պարտադիր վճարներ'!$D$67:$D$71,IFERROR(MATCH($S13,'Մոդելներ և պարտադիր վճարներ'!$F$67:$F$71,1)+1,1))+INDEX('Մոդելներ և պարտադիր վճարներ'!$E$67:$E$71,IFERROR(MATCH($S13,'Մոդելներ և պարտադիր վճարներ'!$F$67:$F$71,1)+1,1)))*'Մոդելներ և պարտադիր վճարներ'!$C$59) -> 207733.33 | Y13: =IF(COUNTIFS('Մոդելներ և պարտադիր վճարներ'!$B$35:$B$37,$D13,'Մոդելներ և պարտադիր վճարներ'!$C$35:$C$37,"ԱՁ")>0,$J13,($T13+INDEX('Մոդելներ և պարտադիր վճարներ'!$D$67:$D$71,IFERROR(MATCH($T13,'Մոդելներ և պարտադիր վճարներ'!$F$67:$F$71,1)+1,1))+INDEX('Մոդելներ և պարտադիր վճարներ'!$E$67:$E$71,IFERROR(MATCH($T13,'Մոդելներ և պարտադիր վճարներ'!$F$67:$F$71,1)+1,1)))*'Մոդելներ և պարտադիր վճարներ'!$C$59) -> 237733.33 | Z13: =IF(COUNTIFS('Մոդելներ և պարտադիր վճարներ'!$B$35:$B$37,$D13,'Մոդելներ և պարտադիր վճարներ'!$C$35:$C$37,"ԱՁ")>0,$J13,($U13+INDEX('Մոդելներ և պարտադիր վճարներ'!$D$67:$D$71,IFERROR(MATCH($U13,'Մոդելներ և պարտադիր վճարներ'!$F$67:$F$71,1)+1,1))+INDEX('Մոդելներ և պարտադիր վճարներ'!$E$67:$E$71,IFERROR(MATCH($U13,'Մոդելներ և պարտադիր վճարներ'!$F$67:$F$71,1)+1,1)))*'Մոդելներ և պարտադիր վճարներ'!$C$59) -> 257733.33 | AA13: =IF(COUNTIFS('Մոդելներ և պարտադիր վճարներ'!$B$35:$B$37,$D13,'Մոդելներ և պարտադիր վճարներ'!$C$35:$C$37,"ԱՁ")>0,$J13,($V13+INDEX('Մոդելներ և պարտադիր վճարներ'!$D$67:$D$71,IFERROR(MATCH($V13,'Մոդելներ և պարտադիր վճարներ'!$F$67:$F$71,1)+1,1))+INDEX('Մոդելներ և պարտադիր վճարներ'!$E$67:$E$71,IFERROR(MATCH($V13,'Մոդելներ և պարտադիր վճարներ'!$F$67:$F$71,1)+1,1)))*'Մոդելներ և պարտադիր վճարներ'!$C$59) -> 277733.33 | AB13: =IF(COUNTIFS('Մոդելներ և պարտադիր վճարներ'!$B$35:$B$37,$D13,'Մոդելներ և պարտադիր վճարներ'!$C$35:$C$37,"ԱՁ")>0,$J13,($W13+INDEX('Մոդելներ և պարտադիր վճարներ'!$D$67:$D$71,IFERROR(MATCH($W13,'Մոդելներ և պարտադիր վճարներ'!$F$67:$F$71,1)+1,1))+INDEX('Մոդելներ և պարտադիր վճարներ'!$E$67:$E$71,IFERROR(MATCH($W13,'Մոդելներ և պարտադիր վճարներ'!$F$67:$F$71,1)+1,1)))*'Մոդելներ և պարտադիր վճարներ'!$C$59) -> 307733.33 | AC13: =IF(COUNTIFS('Մոդելներ և պարտադիր վճարներ'!$B$35:$B$37,$D13,'Մոդելներ և պարտադիր վճարներ'!$C$35:$C$37,"ԱՁ")>0,"Աստիճաններ չեն կիրառվում — հաշիվ-ապրանքագիր",IF(COUNTIFS('Մոդելներ և պարտադիր վճարներ'!$B$35:$B$37,$D13,'Մոդելներ և պարտադիր վճարներ'!$C$35:$C$37,"D2D")>0,"Աստիճաններ չեն կիրառվում — տես D2D բաժինը","Ֆիքս × (1 + աստիճանի %)")) -> Ֆիքս × (1 + աստիճանի %) | AD13: Մարքեթինգի ղեկավար
